Workbook
Name budget: 'Budget Dashboard'!$L1
Name budget_range: 'Budget Dashboard'!$Q1
Name budget_rank: 'Budget Dashboard'!$R1
Name cc_budget: Calculations!$K1
Name cc_delta: Calculations!$L1
Name cc_in_focus: Calculations!$G1
Name cc_month_number: Calculations!$F1
Name cc_show_remaining_budget: Calculations!$I1
Name cc_show_type: Calculations!$H1
Name cc_tracked: Calculations!$J1
Name cc_type: Calculations!$E1
Name comb_rank: 'Budget Dashboard'!$S1
Name comb_rank_norm: 'Budget Dashboard'!$U1
Name comb_rank_norm_run_range: 'Budget Dashboard'!$V1
Name comb_rank_range: 'Budget Dashboard'!$T1
Name comb_rank_unique: 'Budget Dashboard'!$W1
Name current_date: TODAY()
Name expenses_header_row: ROW(Expenses[[#Headers],[Expenses]])
Name expenses_max_row: MAX(ROW(Expenses[]))
Name expenses_min_row: MIN(ROW(Expenses[]))
Name expenses_total_row: ROW('Budget Planning'!$C$37)
Name header_row_id: 'Budget Dashboard'!$D1
Name income_header_row: ROW(income[[#Headers],[Income]])
Name income_max_row: MAX(ROW(income[]))
Name income_min_row: MIN(ROW(income[]))
Name income_total_row: ROW('Budget Planning'!$C$22)
Name is_cat: 'Budget Dashboard'!$F1
Name is_empty: 'Budget Dashboard'!$H1
Name is_header: 'Budget Dashboard'!$E1
Name is_total: 'Budget Dashboard'!$G1
Name items: 'Budget Dashboard'!$J1
Name out_budget: 'Budget Dashboard'!$AA1
Name out_percentage_completed: 'Budget Dashboard'!$AB1
Name out_tracked: 'Budget Dashboard'!$Z1
Name row_id: 'Budget Dashboard'!$C1
Name Savings_header_row: ROW(Savings[[#Headers],[Savings]])
Name Savings_max_row: MAX(ROW(Savings[]))
Name Savings_min_row: MIN(ROW(Savings[]))
Name Savings_rate_calculation_type: Settings!$E$22
Name Savings_total_row: ROW('Budget Planning'!$C$51)
Name selected_period: Calculations!$E$20
Name selected_period_display: Calculations!$E$21
Name selected_year: Calculations!$E$19
Name shift_late_income_starting_day: Settings!$E$18
Name shift_late_income_status: Settings!$E$16
Name sort_max_row: 'Budget Dashboard'!$N1
Name sort_min_row: 'Budget Dashboard'!$M1
Name starting_year: Settings!$E$8
Name tracked: 'Budget Dashboard'!$K1
Name tracked_range: 'Budget Dashboard'!$O1
Name tracked_rank: 'Budget Dashboard'!$P1
Name type: 'Budget Dashboard'!$I1

Sheet Settings
C2: Settings
C6: General
D8: Starting Year : | E8: 2022 | G8: Set the starting year(yyyy) once at the beginning and do not change it again
C12: Budget Tracking & Dashboard
D14: Late Monthly Income
D16: Shift late income: | E16: Active | G16: Activate this option to treat late income received on or after a certain day of the month as income for the next month. This is especially recommended in case you receive your monthly paycheck towards the end of the month and prefer to consider this income as the disposable income for the next month.
D18: Starting on day x in month: | E18: 20
D20: KPI Calculation in Dashboard
D22: Savings Rate as % of Income: | E22: % allocated to Savings | G22: Choose how you want the savings rate (SR) to be calculated in the dashboard KPI tiles:
G23: 1)Active Option (% allocated to Savings): SR = Savings / Income
G24: 2)Passive Option( % not allocated to Expenses): SR = (Income - Expenses)/Income

Sheet Budget Planning
C2: Budget Planning
C5: Define starting year in settings | E5: =starting_year -> 2022 | S5: =E5+1 -> 2023 | AG5: =S5+1 -> 2024 | AU5: =AG5+1 -> 2025 | BI5: =AU5+1 -> 2026 | BW5: =BI5+1 -> 2027 | CK5: =BW5+1 -> 2028 | CY5: =CK5+1 -> 2029 | DM5: =CY5+1 -> 2030 | EA5: =DM5+1 -> 2031 | EO5: =EA5+1 -> 2032
E6: =IF(E7=0,"Jan ✓","Jan") -> Jan ✓ | F6: =IF(F7=0,"Feb ✓","Feb") -> Feb ✓ | G6: =IF(G7=0,"Mar ✓","Mar") -> Mar ✓ | H6: =IF(H7=0,"Apr ✓","Apr") -> Apr ✓ | I6: =IF(I7=0,"May ✓","May") -> May ✓ | J6: =IF(J7=0,"Jun ✓","Jun") -> Jun ✓ | K6: =IF(K7=0,"Jul ✓","Jul") -> Jul ✓ | L6: =IF(L7=0,"Aug ✓","Aug") -> Aug ✓ | M6: =IF(M7=0,"Sep ✓","Sep") -> Sep ✓ | N6: =IF(N7=0,"Oct ✓","Oct") -> Oct ✓ | O6: =IF(O7=0,"Nov ✓","Nov") -> Nov ✓ | P6: =IF(P7=0,"Dec ✓","Dec") -> Dec ✓ | Q6: =IF(Q7=0,"Total ✓","Total") -> Total ✓ | S6: =IF(S7=0,"Jan ✓","Jan") -> Jan ✓ | T6: =IF(T7=0,"Feb ✓","Feb") -> Feb ✓ | U6: =IF(U7=0,"Mar ✓","Mar") -> Mar ✓ | V6: =IF(V7=0,"Apr ✓","Apr") -> Apr ✓ | W6: =IF(W7=0,"May ✓","May") -> May ✓ | X6: =IF(X7=0,"Jun ✓","Jun") -> Jun ✓ | Y6: =IF(Y7=0,"Jul ✓","Jul") -> Jul ✓ | Z6: =IF(Z7=0,"Aug ✓","Aug") -> Aug ✓ | AA6: =IF(AA7=0,"Sep ✓","Sep") -> Sep ✓ | AB6: =IF(AB7=0,"Oct ✓","Oct") -> Oct ✓ | AC6: =IF(AC7=0,"Nov ✓","Nov") -> Nov ✓ | AD6: =IF(AD7=0,"Dec ✓","Dec") -> Dec ✓ | AE6: =IF(AE7=0,"Total ✓","Total") -> Total ✓ | AG6: =IF(AG7=0,"Jan ✓","Jan") -> Jan ✓ | AH6: =IF(AH7=0,"Feb ✓","Feb") -> Feb ✓ | AI6: =IF(AI7=0,"Mar ✓","Mar") -> Mar ✓ | AJ6: =IF(AJ7=0,"Apr ✓","Apr") -> Apr ✓ | AK6: =IF(AK7=0,"May ✓","May") -> May ✓ | AL6: =IF(AL7=0,"Jun ✓","Jun") -> Jun ✓ | AM6: =IF(AM7=0,"Jul ✓","Jul") -> Jul ✓ | AN6: =IF(AN7=0,"Aug ✓","Aug") -> Aug ✓ | AO6: =IF(AO7=0,"Sep ✓","Sep") -> Sep ✓ | AP6: =IF(AP7=0,"Oct ✓","Oct") -> Oct ✓ | AQ6: =IF(AQ7=0,"Nov ✓","Nov") -> Nov ✓ | AR6: =IF(AR7=0,"Dec ✓","Dec") -> Dec ✓ | AS6: =IF(AS7=0,"Total ✓","Total") -> Total ✓ | AU6: =IF(AU7=0,"Jan ✓","Jan") -> Jan ✓ | AV6: =IF(AV7=0,"Feb ✓","Feb") -> Feb ✓ | AW6: =IF(AW7=0,"Mar ✓","Mar") -> Mar ✓ | AX6: =IF(AX7=0,"Apr ✓","Apr") -> Apr ✓ | AY6: =IF(AY7=0,"May ✓","May") -> May ✓ | AZ6: =IF(AZ7=0,"Jun ✓","Jun") -> Jun ✓ | BA6: =IF(BA7=0,"Jul ✓","Jul") -> Jul ✓ | BB6: =IF(BB7=0,"Aug ✓","Aug") -> Aug ✓ | BC6: =IF(BC7=0,"Sep ✓","Sep") -> Sep ✓ | BD6: =IF(BD7=0,"Oct ✓","Oct") -> Oct ✓ | BE6: =IF(BE7=0,"Nov ✓","Nov") -> Nov ✓ | BF6: =IF(BF7=0,"Dec ✓","Dec") -> Dec ✓ | BG6: =IF(BG7=0,"Total ✓","Total") -> Total ✓ | BI6: =IF(BI7=0,"Jan ✓","Jan") -> Jan ✓ | BJ6: =IF(BJ7=0,"Feb ✓","Feb") -> Feb ✓ | BK6: =IF(BK7=0,"Mar ✓","Mar") -> Mar ✓ | BL6: =IF(BL7=0,"Apr ✓","Apr") -> Apr ✓ | BM6: =IF(BM7=0,"May ✓","May") -> May ✓ | BN6: =IF(BN7=0,"Jun ✓","Jun") -> Jun ✓ | BO6: =IF(BO7=0,"Jul ✓","Jul") -> Jul ✓ | BP6: =IF(BP7=0,"Aug ✓","Aug") -> Aug ✓ | BQ6: =IF(BQ7=0,"Sep ✓","Sep") -> Sep ✓ | BR6: =IF(BR7=0,"Oct ✓","Oct") -> Oct ✓ | BS6: =IF(BS7=0,"Nov ✓","Nov") -> Nov ✓ | BT6: =IF(BT7=0,"Dec ✓","Dec") -> Dec ✓ | BU6: =IF(BU7=0,"Total ✓","Total") -> Total ✓ | BW6: =IF(BW7=0,"Jan ✓","Jan") -> Jan ✓ | BX6: =IF(BX7=0,"Feb ✓","Feb") -> Feb ✓ | BY6: =IF(BY7=0,"Mar ✓","Mar") -> Mar ✓ | BZ6: =IF(BZ7=0,"Apr ✓","Apr") -> Apr ✓ | CA6: =IF(CA7=0,"May ✓","May") -> May ✓ | CB6: =IF(CB7=0,"Jun ✓","Jun") -> Jun ✓ | CC6: =IF(CC7=0,"Jul ✓","Jul") -> Jul ✓ | CD6: =IF(CD7=0,"Aug ✓","Aug") -> Aug ✓ | CE6: =IF(CE7=0,"Sep ✓","Sep") -> Sep ✓ | CF6: =IF(CF7=0,"Oct ✓","Oct") -> Oct ✓ | CG6: =IF(CG7=0,"Nov ✓","Nov") -> Nov ✓ | CH6: =IF(CH7=0,"Dec ✓","Dec") -> Dec ✓ | CI6: =IF(CI7=0,"Total ✓","Total") -> Total ✓ | CK6: =IF(CK7=0,"Jan ✓","Jan") -> Jan ✓ | CL6: =IF(CL7=0,"Feb ✓","Feb") -> Feb ✓ | CM6: =IF(CM7=0,"Mar ✓","Mar") -> Mar ✓ | CN6: =IF(CN7=0,"Apr ✓","Apr") -> Apr ✓ | CO6: =IF(CO7=0,"May ✓","May") -> May ✓ | CP6: =IF(CP7=0,"Jun ✓","Jun") -> Jun ✓ | CQ6: =IF(CQ7=0,"Jul ✓","Jul") -> Jul ✓ | CR6: =IF(CR7=0,"Aug ✓","Aug") -> Aug ✓ | CS6: =IF(CS7=0,"Sep ✓","Sep") -> Sep ✓ | CT6: =IF(CT7=0,"Oct ✓","Oct") -> Oct ✓ | CU6: =IF(CU7=0,"Nov ✓","Nov") -> Nov ✓ | CV6: =IF(CV7=0,"Dec ✓","Dec") -> Dec ✓ | CW6: =IF(CW7=0,"Total ✓","Total") -> Total ✓ | CY6: =IF(CY7=0,"Jan ✓","Jan") -> Jan ✓ | CZ6: =IF(CZ7=0,"Feb ✓","Feb") -> Feb ✓ | DA6: =IF(DA7=0,"Mar ✓","Mar") -> Mar ✓ | DB6: =IF(DB7=0,"Apr ✓","Apr") -> Apr ✓ | DC6: =IF(DC7=0,"May ✓","May") -> May ✓ | DD6: =IF(DD7=0,"Jun ✓","Jun") -> Jun ✓ | DE6: =IF(DE7=0,"Jul ✓","Jul") -> Jul ✓ | DF6: =IF(DF7=0,"Aug ✓","Aug") -> Aug ✓ | DG6: =IF(DG7=0,"Sep ✓","Sep") -> Sep ✓ | DH6: =IF(DH7=0,"Oct ✓","Oct") -> Oct ✓ | DI6: =IF(DI7=0,"Nov ✓","Nov") -> Nov ✓ | DJ6: =IF(DJ7=0,"Dec ✓","Dec") -> Dec ✓ | DK6: =IF(DK7=0,"Total ✓","Total") -> Total ✓ | DM6: =IF(DM7=0,"Jan ✓","Jan") -> Jan ✓ | DN6: =IF(DN7=0,"Feb ✓","Feb") -> Feb ✓ | DO6: =IF(DO7=0,"Mar ✓","Mar") -> Mar ✓ | DP6: =IF(DP7=0,"Apr ✓","Apr") -> Apr ✓ | DQ6: =IF(DQ7=0,"May ✓","May") -> May ✓ | DR6: =IF(DR7=0,"Jun ✓","Jun") -> Jun ✓ | DS6: =IF(DS7=0,"Jul ✓","Jul") -> Jul ✓ | DT6: =IF(DT7=0,"Aug ✓","Aug") -> Aug ✓ | DU6: =IF(DU7=0,"Sep ✓","Sep") -> Sep ✓ | DV6: =IF(DV7=0,"Oct ✓","Oct") -> Oct ✓ | DW6: =IF(DW7=0,"Nov ✓","Nov") -> Nov ✓ | DX6: =IF(DX7=0,"Dec ✓","Dec") -> Dec ✓ | DY6: =IF(DY7=0,"Total ✓","Total") -> Total ✓ | EA6: =IF(EA7=0,"Jan ✓","Jan") -> Jan ✓ | EB6: =IF(EB7=0,"Feb ✓","Feb") -> Feb ✓ | EC6: =IF(EC7=0,"Mar ✓","Mar") -> Mar ✓ | ED6: =IF(ED7=0,"Apr ✓","Apr") -> Apr ✓ | EE6: =IF(EE7=0,"May ✓","May") -> May ✓ | EF6: =IF(EF7=0,"Jun ✓","Jun") -> Jun ✓ | EG6: =IF(EG7=0,"Jul ✓","Jul") -> Jul ✓ | EH6: =IF(EH7=0,"Aug ✓","Aug") -> Aug ✓ | EI6: =IF(EI7=0,"Sep ✓","Sep") -> Sep ✓ | EJ6: =IF(EJ7=0,"Oct ✓","Oct") -> Oct ✓ | EK6: =IF(EK7=0,"Nov ✓","Nov") -> Nov ✓ | EL6: =IF(EL7=0,"Dec ✓","Dec") -> Dec ✓ | EM6: =IF(EM7=0,"Total ✓","Total") -> Total ✓ | EO6: =IF(EO7=0,"Jan ✓","Jan") -> Jan ✓ | EP6: =IF(EP7=0,"Feb ✓","Feb") -> Feb ✓ | EQ6: =IF(EQ7=0,"Mar ✓","Mar") -> Mar ✓ | ER6: =IF(ER7=0,"Apr ✓","Apr") -> Apr ✓ | ES6: =IF(ES7=0,"May ✓","May") -> May ✓ | ET6: =IF(ET7=0,"Jun ✓","Jun") -> Jun ✓ | EU6: =IF(EU7=0,"Jul ✓","Jul") -> Jul ✓ | EV6: =IF(EV7=0,"Aug ✓","Aug") -> Aug ✓ | EW6: =IF(EW7=0,"Sep ✓","Sep") -> Sep ✓ | EX6: =IF(EX7=0,"Oct ✓","Oct") -> Oct ✓ | EY6: =IF(EY7=0,"Nov ✓","Nov") -> Nov ✓ | EZ6: =IF(EZ7=0,"Dec ✓","Dec") -> Dec ✓ | FA6: =IF(FA7=0,"Total ✓","Total") -> Total ✓
C7: To be allocated | E7: =E22 -(E37 + E51) -> 0 | F7: =F22 -(F37 + F51) -> 0 | G7: =G22 -(G37 + G51) -> 0 | H7: =H22 -(H37 + H51) -> 0 | I7: =I22 -(I37 + I51) -> 0 | J7: =J22 -(J37 + J51) -> 0 | K7: =K22 -(K37 + K51) -> 0 | L7: =L22 -(L37 + L51) -> 0 | ... Q7: =Q22 -(Q37 + Q51) -> 0 | S7: =S22 -(S37 + S51) -> 0 | T7: =T22 -(T37 + T51) -> 0 | U7: =U22 -(U37 + U51) -> 0 | V7: =V22 -(V37 + V51) -> 0 | W7: =W22 -(W37 + W51) -> 0 | X7: =X22 -(X37 + X51) -> 0 | Y7: =Y22 -(Y37 + Y51) -> 0 | Z7: =Z22 -(Z37 + Z51) -> 0 | ... AE7: =AE22 -(AE37 + AE51) -> 0 | AG7: =AG22 -(AG37 + AG51) -> 0 | AH7: =AH22 -(AH37 + AH51) -> 0 | AI7: =AI22 -(AI37 + AI51) -> 0 | AJ7: =AJ22 -(AJ37 + AJ51) -> 0 | AK7: =AK22 -(AK37 + AK51) -> 0 | AL7: =AL22 -(AL37 + AL51) -> 0 | AM7: =AM22 -(AM37 + AM51) -> 0 | AN7: =AN22 -(AN37 + AN51) -> 0 | ... AS7: =AS22 -(AS37 + AS51) -> 0 | AU7: =AU22 -(AU37 + AU51) -> 0 | AV7: =AV22 -(AV37 + AV51) -> 0 | AW7: =AW22 -(AW37 + AW51) -> 0 | AX7: =AX22 -(AX37 + AX51) -> 0 | AY7: =AY22 -(AY37 + AY51) -> 0 | AZ7: =AZ22 -(AZ37 + AZ51) -> 0 | BA7: =BA22 -(BA37 + BA51) -> 0 | BB7: =BB22 -(BB37 + BB51) -> 0 | ... BG7: =BG22 -(BG37 + BG51) -> 0 | BI7: =BI22 -(BI37 + BI51) -> 0 | BJ7: =BJ22 -(BJ37 + BJ51) -> 0 | BK7: =BK22 -(BK37 + BK51) -> 0 | BL7: =BL22 -(BL37 + BL51) -> 0 | BM7: =BM22 -(BM37 + BM51) -> 0 | BN7: =BN22 -(BN37 + BN51) -> 0 | BO7: =BO22 -(BO37 + BO51) -> 0 | BP7: =BP22 -(BP37 + BP51) -> 0 | ... BU7: =BU22 -(BU37 + BU51) -> 0 | BW7: =BW22 -(BW37 + BW51) -> 0 | BX7: =BX22 -(BX37 + BX51) -> 0 | BY7: =BY22 -(BY37 + BY51) -> 0 | BZ7: =BZ22 -(BZ37 + BZ51) -> 0 | CA7: =CA22 -(CA37 + CA51) -> 0 | CB7: =CB22 -(CB37 + CB51) -> 0 | CC7: =CC22 -(CC37 + CC51) -> 0 | CD7: =CD22 -(CD37 + CD51) -> 0 | ... CI7: =CI22 -(CI37 + CI51) -> 0 | CK7: =CK22 -(CK37 + CK51) -> 0 | CL7: =CL22 -(CL37 + CL51) -> 0 | CM7: =CM22 -(CM37 + CM51) -> 0 | CN7: =CN22 -(CN37 + CN51) -> 0 | CO7: =CO22 -(CO37 + CO51) -> 0 | CP7: =CP22 -(CP37 + CP51) -> 0 | CQ7: =CQ22 -(CQ37 + CQ51) -> 0 | CR7: =CR22 -(CR37 + CR51) -> 0 | ... CW7: =CW22 -(CW37 + CW51) -> 0 | CY7: =CY22 -(CY37 + CY51) -> 0 | CZ7: =CZ22 -(CZ37 + CZ51) -> 0 | DA7: =DA22 -(DA37 + DA51) -> 0 | DB7: =DB22 -(DB37 + DB51) -> 0 | DC7: =DC22 -(DC37 + DC51) -> 0 | DD7: =DD22 -(DD37 + DD51) -> 0 | DE7: =DE22 -(DE37 + DE51) -> 0 | DF7: =DF22 -(DF37 + DF51) -> 0 | ... DK7: =DK22 -(DK37 + DK51) -> 0 | DM7: =DM22 -(DM37 + DM51) -> 0 | DN7: =DN22 -(DN37 + DN51) -> 0 | DO7: =DO22 -(DO37 + DO51) -> 0 | DP7: =DP22 -(DP37 + DP51) -> 0 | DQ7: =DQ22 -(DQ37 + DQ51) -> 0 | DR7: =DR22 -(DR37 + DR51) -> 0 | DS7: =DS22 -(DS37 + DS51) -> 0 | DT7: =DT22 -(DT37 + DT51) -> 0 | ... DY7: =DY22 -(DY37 + DY51) -> 0 | EA7: =EA22 -(EA37 + EA51) -> 0 | EB7: =EB22 -(EB37 + EB51) -> 0 | EC7: =EC22 -(EC37 + EC51) -> 0 | ED7: =ED22 -(ED37 + ED51) -> 0 | EE7: =EE22 -(EE37 + EE51) -> 0 | EF7: =EF22 -(EF37 + EF51) -> 0 | EG7: =EG22 -(EG37 + EG51) -> 0 | EH7: =EH22 -(EH37 + EH51) -> 0 | ... EM7: =EM22 -(EM37 + EM51) -> 0 | EO7: =EO22 -(EO37 + EO51) -> 0 | EP7: =EP22 -(EP37 + EP51) -> 0 | EQ7: =EQ22 -(EQ37 + EQ51) -> 0 | ER7: =ER22 -(ER37 + ER51) -> 0 | ES7: =ES22 -(ES37 + ES51) -> 0 | ET7: =ET22 -(ET37 + ET51) -> 0 | EU7: =EU22 -(EU37 + EU51) -> 0 | EV7: =EV22 -(EV37 + EV51) -> 0 | ... FA7: =FA22 -(FA37 + FA51) -> 0
C9: Income | E9: =DATE(E$5,1,1) -> 44562 | F9: =DATE(E$5,2,1) -> 44593 | G9: =DATE(E$5,3,1) -> 44621 | H9: =DATE(E$5,4,1) -> 44652 | I9: =DATE(E$5,5,1) -> 44682 | J9: =DATE(E$5,6,1) -> 44713 | K9: =DATE(E$5,7,1) -> 44743 | L9: =DATE(E$5,8,1) -> 44774 | M9: =DATE(E$5,9,1) -> 44805 | N9: =DATE(E$5,10,1) -> 44835 | O9: =DATE(E$5,11,1) -> 44866 | P9: =DATE(E$5,12,1) -> 44896 | Q9: =E$5 -> 2022 | S9: =DATE(S$5,1,1) -> 44927 | T9: =DATE(S$5,2,1) -> 44958 | U9: =DATE(S$5,3,1) -> 44986 | V9: =DATE(S$5,4,1) -> 45017 | W9: =DATE(S$5,5,1) -> 45047 | X9: =DATE(S$5,6,1) -> 45078 | Y9: =DATE(S$5,7,1) -> 45108 | Z9: =DATE(S$5,8,1) -> 45139 | AA9: =DATE(S$5,9,1) -> 45170 | AB9: =DATE(S$5,10,1) -> 45200 | AC9: =DATE(S$5,11,1) -> 45231 | AD9: =DATE(S$5,12,1) -> 45261 | AE9: =S$5 -> 2023 | AG9: =DATE(AG$5,1,1) -> 45292 | AH9: =DATE(AG$5,2,1) -> 45323 | AI9: =DATE(AG$5,3,1) -> 45352 | AJ9: =DATE(AG$5,4,1) -> 45383 | AK9: =DATE(AG$5,5,1) -> 45413 | AL9: =DATE(AG$5,6,1) -> 45444 | AM9: =DATE(AG$5,7,1) -> 45474 | AN9: =DATE(AG$5,8,1) -> 45505 | AO9: =DATE(AG$5,9,1) -> 45536 | AP9: =DATE(AG$5,10,1) -> 45566 | AQ9: =DATE(AG$5,11,1) -> 45597 | AR9: =DATE(AG$5,12,1) -> 45627 | AS9: =AG$5 -> 2024 | AU9: =DATE(AU$5,1,1) -> 45658 | AV9: =DATE(AU$5,2,1) -> 45689 | AW9: =DATE(AU$5,3,1) -> 45717 | AX9: =DATE(AU$5,4,1) -> 45748 | AY9: =DATE(AU$5,5,1) -> 45778 | AZ9: =DATE(AU$5,6,1) -> 45809 | BA9: =DATE(AU$5,7,1) -> 45839 | BB9: =DATE(AU$5,8,1) -> 45870 | BC9: =DATE(AU$5,9,1) -> 45901 | BD9: =DATE(AU$5,10,1) -> 45931 | BE9: =DATE(AU$5,11,1) -> 45962 | BF9: =DATE(AU$5,12,1) -> 45992 | BG9: =AU$5 -> 2025 | BI9: =DATE(BI$5,1,1) -> 46023 | BJ9: =DATE(BI$5,2,1) -> 46054 | BK9: =DATE(BI$5,3,1) -> 46082 | BL9: =DATE(BI$5,4,1) -> 46113 | BM9: =DATE(BI$5,5,1) -> 46143 | BN9: =DATE(BI$5,6,1) -> 46174 | BO9: =DATE(BI$5,7,1) -> 46204 | BP9: =DATE(BI$5,8,1) -> 46235 | BQ9: =DATE(BI$5,9,1) -> 46266 | BR9: =DATE(BI$5,10,1) -> 46296 | BS9: =DATE(BI$5,11,1) -> 46327 | BT9: =DATE(BI$5,12,1) -> 46357 | BU9: =BI$5 -> 2026 | BW9: =DATE(BW$5,1,1) -> 46388 | BX9: =DATE(BW$5,2,1) -> 46419 | BY9: =DATE(BW$5,3,1) -> 46447 | BZ9: =DATE(BW$5,4,1) -> 46478 | CA9: =DATE(BW$5,5,1) -> 46508 | CB9: =DATE(BW$5,6,1) -> 46539 | CC9: =DATE(BW$5,7,1) -> 46569 | CD9: =DATE(BW$5,8,1) -> 46600 | CE9: =DATE(BW$5,9,1) -> 46631 | CF9: =DATE(BW$5,10,1) -> 46661 | CG9: =DATE(BW$5,11,1) -> 46692 | CH9: =DATE(BW$5,12,1) -> 46722 | CI9: =BW$5 -> 2027 | CK9: =DATE(CK$5,1,1) -> 46753 | CL9: =DATE(CK$5,2,1) -> 46784 | CM9: =DATE(CK$5,3,1) -> 46813 | CN9: =DATE(CK$5,4,1) -> 46844 | CO9: =DATE(CK$5,5,1) -> 46874 | CP9: =DATE(CK$5,6,1) -> 46905 | CQ9: =DATE(CK$5,7,1) -> 46935 | CR9: =DATE(CK$5,8,1) -> 46966 | CS9: =DATE(CK$5,9,1) -> 46997 | CT9: =DATE(CK$5,10,1) -> 47027 | CU9: =DATE(CK$5,11,1) -> 47058 | CV9: =DATE(CK$5,12,1) -> 47088 | CW9: =CK$5 -> 2028 | CY9: =DATE(CY$5,1,1) -> 47119 | CZ9: =DATE(CY$5,2,1) -> 47150 | DA9: =DATE(CY$5,3,1) -> 47178 | DB9: =DATE(CY$5,4,1) -> 47209 | DC9: =DATE(CY$5,5,1) -> 47239 | DD9: =DATE(CY$5,6,1) -> 47270 | DE9: =DATE(CY$5,7,1) -> 47300 | DF9: =DATE(CY$5,8,1) -> 47331 | DG9: =DATE(CY$5,9,1) -> 47362 | DH9: =DATE(CY$5,10,1) -> 47392 | DI9: =DATE(CY$5,11,1) -> 47423 | DJ9: =DATE(CY$5,12,1) -> 47453 | DK9: =CY$5 -> 2029 | DM9: =DATE(DM$5,1,1) -> 47484 | DN9: =DATE(DM$5,2,1) -> 47515 | DO9: =DATE(DM$5,3,1) -> 47543 | DP9: =DATE(DM$5,4,1) -> 47574 | DQ9: =DATE(DM$5,5,1) -> 47604 | DR9: =DATE(DM$5,6,1) -> 47635 | DS9: =DATE(DM$5,7,1) -> 47665 | DT9: =DATE(DM$5,8,1) -> 47696 | DU9: =DATE(DM$5,9,1) -> 47727 | DV9: =DATE(DM$5,10,1) -> 47757 | DW9: =DATE(DM$5,11,1) -> 47788 | DX9: =DATE(DM$5,12,1) -> 47818 | DY9: =DM$5 -> 2030 | EA9: =DATE(EA$5,1,1) -> 47849 | EB9: =DATE(EA$5,2,1) -> 47880 | EC9: =DATE(EA$5,3,1) -> 47908 | ED9: =DATE(EA$5,4,1) -> 47939 | EE9: =DATE(EA$5,5,1) -> 47969 | EF9: =DATE(EA$5,6,1) -> 48000 | EG9: =DATE(EA$5,7,1) -> 48030 | EH9: =DATE(EA$5,8,1) -> 48061 | EI9: =DATE(EA$5,9,1) -> 48092 | EJ9: =DATE(EA$5,10,1) -> 48122 | EK9: =DATE(EA$5,11,1) -> 48153 | EL9: =DATE(EA$5,12,1) -> 48183 | EM9: =EA$5 -> 2031 | EO9: =DATE(EO$5,1,1) -> 48214 | EP9: =DATE(EO$5,2,1) -> 48245 | EQ9: =DATE(EO$5,3,1) -> 48274 | ER9: =DATE(EO$5,4,1) -> 48305 | ES9: =DATE(EO$5,5,1) -> 48335 | ET9: =DATE(EO$5,6,1) -> 48366 | EU9: =DATE(EO$5,7,1) -> 48396 | EV9: =DATE(EO$5,8,1) -> 48427 | EW9: =DATE(EO$5,9,1) -> 48458 | EX9: =DATE(EO$5,10,1) -> 48488 | EY9: =DATE(EO$5,11,1) -> 48519 | EZ9: =DATE(EO$5,12,1) -> 48549 | FA9: =EO$5 -> 2032
C10: Employement | E10: 3500 | F10: 3500 | G10: 3500 | H10: 4500 | I10: 4500 | J10: 4500 | K10: 4500 | L10: 4500 | M10: 4500 | N10: 4500 | O10: 4500 | P10: 4500 | Q10: =SUM(E10:P10) -> 51000 | AE10: =SUM(S10:AD10) -> 0 | AS10: =SUM(AG10:AR10) -> 0 | BG10: =SUM(AU10:BF10) -> 0 | BU10: =SUM(BI10:BT10) -> 0 | CI10: =SUM(BW10:CH10) -> 0 | CW10: =SUM(CK10:CV10) -> 0 | DK10: =SUM(CY10:DJ10) -> 0 | DY10: =SUM(DM10:DX10) -> 0 | EM10: =SUM(EA10:EL10) -> 0 | FA10: =SUM(EO10:EZ10) -> 0
C11: Side hustle | E11: 1000 | F11: 1000 | G11: 1000 | H11: 1000 | I11: 1000 | J11: 1000 | K11: 1000 | L11: 1000 | M11: 1000 | N11: 1000 | O11: 1000 | P11: 1000 | Q11: =SUM(E11:P11) -> 12000 | AE11: =SUM(S11:AD11) -> 0 | AS11: =SUM(AG11:AR11) -> 0 | BG11: =SUM(AU11:BF11) -> 0 | BU11: =SUM(BI11:BT11) -> 0 | CI11: =SUM(BW11:CH11) -> 0 | CW11: =SUM(CK11:CV11) -> 0 | DK11: =SUM(CY11:DJ11) -> 0 | DY11: =SUM(DM11:DX11) -> 0 | EM11: =SUM(EA11:EL11) -> 0 | FA11: =SUM(EO11:EZ11) -> 0
C12: Dividends | E12: 150 | F12: 50 | G12: 100 | H12: 150 | I12: 50 | J12: 100 | K12: 150 | L12: 50 | M12: 100 | N12: 150 | O12: 50 | P12: 100 | Q12: =SUM(E12:P12) -> 1200 | AE12: =SUM(S12:AD12) -> 0 | AS12: =SUM(AG12:AR12) -> 0 | BG12: =SUM(AU12:BF12) -> 0 | BU12: =SUM(BI12:BT12) -> 0 | CI12: =SUM(BW12:CH12) -> 0 | CW12: =SUM(CK12:CV12) -> 0 | DK12: =SUM(CY12:DJ12) -> 0 | DY12: =SUM(DM12:DX12) -> 0 | EM12: =SUM(EA12:EL12) -> 0 | FA12: =SUM(EO12:EZ12) -> 0
C13: Enter income category | Q13: =SUM(E13:P13) -> 0 | AE13: =SUM(S13:AD13) -> 0 | AS13: =SUM(AG13:AR13) -> 0 | BG13: =SUM(AU13:BF13) -> 0 | BU13: =SUM(BI13:BT13) -> 0 | CI13: =SUM(BW13:CH13) -> 0 | CW13: =SUM(CK13:CV13) -> 0 | DK13: =SUM(CY13:DJ13) -> 0 | DY13: =SUM(DM13:DX13) -> 0 | EM13: =SUM(EA13:EL13) -> 0 | FA13: =SUM(EO13:EZ13) -> 0
C14: Enter income category | Q14: =SUM(E14:P14) -> 0 | AE14: =SUM(S14:AD14) -> 0 | AS14: =SUM(AG14:AR14) -> 0 | BG14: =SUM(AU14:BF14) -> 0 | BU14: =SUM(BI14:BT14) -> 0 | CI14: =SUM(BW14:CH14) -> 0 | CW14: =SUM(CK14:CV14) -> 0 | DK14: =SUM(CY14:DJ14) -> 0 | DY14: =SUM(DM14:DX14) -> 0 | EM14: =SUM(EA14:EL14) -> 0 | FA14: =SUM(EO14:EZ14) -> 0
C15: Enter income category | Q15: =SUM(E15:P15) -> 0 | AE15: =SUM(S15:AD15) -> 0 | AS15: =SUM(AG15:AR15) -> 0 | BG15: =SUM(AU15:BF15) -> 0 | BU15: =SUM(BI15:BT15) -> 0 | CI15: =SUM(BW15:CH15) -> 0 | CW15: =SUM(CK15:CV15) -> 0 | DK15: =SUM(CY15:DJ15) -> 0 | DY15: =SUM(DM15:DX15) -> 0 | EM15: =SUM(EA15:EL15) -> 0 | FA15: =SUM(EO15:EZ15) -> 0
C16: Enter income category | Q16: =SUM(E16:P16) -> 0 | AE16: =SUM(S16:AD16) -> 0 | AS16: =SUM(AG16:AR16) -> 0 | BG16: =SUM(AU16:BF16) -> 0 | BU16: =SUM(BI16:BT16) -> 0 | CI16: =SUM(BW16:CH16) -> 0 | CW16: =SUM(CK16:CV16) -> 0 | DK16: =SUM(CY16:DJ16) -> 0 | DY16: =SUM(DM16:DX16) -> 0 | EM16: =SUM(EA16:EL16) -> 0 | FA16: =SUM(EO16:EZ16) -> 0
C17: Enter income category | Q17: =SUM(E17:P17) -> 0 | AE17: =SUM(S17:AD17) -> 0 | AS17: =SUM(AG17:AR17) -> 0 | BG17: =SUM(AU17:BF17) -> 0 | BU17: =SUM(BI17:BT17) -> 0 | CI17: =SUM(BW17:CH17) -> 0 | CW17: =SUM(CK17:CV17) -> 0 | DK17: =SUM(CY17:DJ17) -> 0 | DY17: =SUM(DM17:DX17) -> 0 | EM17: =SUM(EA17:EL17) -> 0 | FA17: =SUM(EO17:EZ17) -> 0
C18: Enter income category | Q18: =SUM(E18:P18) -> 0 | AE18: =SUM(S18:AD18) -> 0 | AS18: =SUM(AG18:AR18) -> 0 | BG18: =SUM(AU18:BF18) -> 0 | BU18: =SUM(BI18:BT18) -> 0 | CI18: =SUM(BW18:CH18) -> 0 | CW18: =SUM(CK18:CV18) -> 0 | DK18: =SUM(CY18:DJ18) -> 0 | DY18: =SUM(DM18:DX18) -> 0 | EM18: =SUM(EA18:EL18) -> 0 | FA18: =SUM(EO18:EZ18) -> 0
C19: Enter income category | Q19: =SUM(E19:P19) -> 0 | AE19: =SUM(S19:AD19) -> 0 | AS19: =SUM(AG19:AR19) -> 0 | BG19: =SUM(AU19:BF19) -> 0 | BU19: =SUM(BI19:BT19) -> 0 | CI19: =SUM(BW19:CH19) -> 0 | CW19: =SUM(CK19:CV19) -> 0 | DK19: =SUM(CY19:DJ19) -> 0 | DY19: =SUM(DM19:DX19) -> 0 | EM19: =SUM(EA19:EL19) -> 0 | FA19: =SUM(EO19:EZ19) -> 0
C20: Enter income category | Q20: =SUM(E20:P20) -> 0 | AE20: =SUM(S20:AD20) -> 0 | AS20: =SUM(AG20:AR20) -> 0 | BG20: =SUM(AU20:BF20) -> 0 | BU20: =SUM(BI20:BT20) -> 0 | CI20: =SUM(BW20:CH20) -> 0 | CW20: =SUM(CK20:CV20) -> 0 | DK20: =SUM(CY20:DJ20) -> 0 | DY20: =SUM(DM20:DX20) -> 0 | EM20: =SUM(EA20:EL20) -> 0 | FA20: =SUM(EO20:EZ20) -> 0
C21: Enter income category | Q21: =SUM(E21:P21) -> 0 | AE21: =SUM(S21:AD21) -> 0 | AS21: =SUM(AG21:AR21) -> 0 | BG21: =SUM(AU21:BF21) -> 0 | BU21: =SUM(BI21:BT21) -> 0 | CI21: =SUM(BW21:CH21) -> 0 | CW21: =SUM(CK21:CV21) -> 0 | DK21: =SUM(CY21:DJ21) -> 0 | DY21: =SUM(DM21:DX21) -> 0 | EM21: =SUM(EA21:EL21) -> 0 | FA21: =SUM(EO21:EZ21) -> 0
C22: Total | E22: =SUM(INDIRECT(ADDRESS(income_min_row,COLUMN())& ":"& ADDRESS(income_max_row,COLUMN()))) -> 4650 | F22: =SUM(INDIRECT(ADDRESS(income_min_row,COLUMN())& ":"& ADDRESS(income_max_row,COLUMN()))) -> 4550 | G22: =SUM(INDIRECT(ADDRESS(income_min_row,COLUMN())& ":"& ADDRESS(income_max_row,COLUMN()))) -> 4600 | H22: =SUM(INDIRECT(ADDRESS(income_min_row,COLUMN())& ":"& ADDRESS(income_max_row,COLUMN()))) -> 5650 | I22: =SUM(INDIRECT(ADDRESS(income_min_row,COLUMN())& ":"& ADDRESS(income_max_row,COLUMN()))) -> 5550 | J22: =SUM(INDIRECT(ADDRESS(income_min_row,COLUMN())& ":"& ADDRESS(income_max_row,COLUMN()))) -> 5600 | K22: =SUM(INDIRECT(ADDRESS(income_min_row,COLUMN())& ":"& ADDRESS(income_max_row,COLUMN()))) -> 5650 | L22: =SUM(INDIRECT(ADDRESS(income_min_row,COLUMN())& ":"& ADDRESS(income_max_row,COLUMN()))) -> 5550 | ... Q22: =SUM(INDIRECT(ADDRESS(income_min_row,COLUMN())& ":"& ADDRESS(income_max_row,COLUMN()))) -> 64200 | S22: =SUM(INDIRECT(ADDRESS(income_min_row,COLUMN())& ":"& ADDRESS(income_max_row,COLUMN()))) -> 0 | T22: =SUM(INDIRECT(ADDRESS(income_min_row,COLUMN())& ":"& ADDRESS(income_max_row,COLUMN()))) -> 0 | U22: =SUM(INDIRECT(ADDRESS(income_min_row,COLUMN())& ":"& ADDRESS(income_max_row,COLUMN()))) -> 0 | V22: =SUM(INDIRECT(ADDRESS(income_min_row,COLUMN())& ":"& ADDRESS(income_max_row,COLUMN()))) -> 0 | W22: =SUM(INDIRECT(ADDRESS(income_min_row,COLUMN())& ":"& ADDRESS(income_max_row,COLUMN()))) -> 0 | X22: =SUM(INDIRECT(ADDRESS(income_min_row,COLUMN())& ":"& ADDRESS(income_max_row,COLUMN()))) -> 0 | Y22: =SUM(INDIRECT(ADDRESS(income_min_row,COLUMN())& ":"& ADDRESS(income_max_row,COLUMN()))) -> 0 | Z22: =SUM(INDIRECT(ADDRESS(income_min_row,COLUMN())& ":"& ADDRESS(income_max_row,COLUMN()))) -> 0 | ... AE22: =SUM(INDIRECT(ADDRESS(income_min_row,COLUMN())& ":"& ADDRESS(income_max_row,COLUMN()))) -> 0 | AG22: =SUM(INDIRECT(ADDRESS(income_min_row,COLUMN())& ":"& ADDRESS(income_max_row,COLUMN()))) -> 0 | AH22: =SUM(INDIRECT(ADDRESS(income_min_row,COLUMN())& ":"& ADDRESS(income_max_row,COLUMN()))) -> 0 | AI22: =SUM(INDIRECT(ADDRESS(income_min_row,COLUMN())& ":"& ADDRESS(income_max_row,COLUMN()))) -> 0 | AJ22: =SUM(INDIRECT(ADDRESS(income_min_row,COLUMN())& ":"& ADDRESS(income_max_row,COLUMN()))) -> 0 | AK22: =SUM(INDIRECT(ADDRESS(income_min_row,COLUMN())& ":"& ADDRESS(income_max_row,COLUMN()))) -> 0 | AL22: =SUM(INDIRECT(ADDRESS(income_min_row,COLUMN())& ":"& ADDRESS(income_max_row,COLUMN()))) -> 0 | AM22: =SUM(INDIRECT(ADDRESS(income_min_row,COLUMN())& ":"& ADDRESS(income_max_row,COLUMN()))) -> 0 | AN22: =SUM(INDIRECT(ADDRESS(income_min_row,COLUMN())& ":"& ADDRESS(income_max_row,COLUMN()))) -> 0 | ... AS22: =SUM(INDIRECT(ADDRESS(income_min_row,COLUMN())& ":"& ADDRESS(income_max_row,COLUMN()))) -> 0 | AU22: =SUM(INDIRECT(ADDRESS(income_min_row,COLUMN())& ":"& ADDRESS(income_max_row,COLUMN()))) -> 0 | AV22: =SUM(INDIRECT(ADDRESS(income_min_row,COLUMN())& ":"& ADDRESS(income_max_row,COLUMN()))) -> 0 | AW22: =SUM(INDIRECT(ADDRESS(income_min_row,COLUMN())& ":"& ADDRESS(income_max_row,COLUMN()))) -> 0 | AX22: =SUM(INDIRECT(ADDRESS(income_min_row,COLUMN())& ":"& ADDRESS(income_max_row,COLUMN()))) -> 0 | AY22: =SUM(INDIRECT(ADDRESS(income_min_row,COLUMN())& ":"& ADDRESS(income_max_row,COLUMN()))) -> 0 | AZ22: =SUM(INDIRECT(ADDRESS(income_min_row,COLUMN())& ":"& ADDRESS(income_max_row,COLUMN()))) -> 0 | BA22: =SUM(INDIRECT(ADDRESS(income_min_row,COLUMN())& ":"& ADDRESS(income_max_row,COLUMN()))) -> 0 | BB22: =SUM(INDIRECT(ADDRESS(income_min_row,COLUMN())& ":"& ADDRESS(income_max_row,COLUMN()))) -> 0 | ... BG22: =SUM(INDIRECT(ADDRESS(income_min_row,COLUMN())& ":"& ADDRESS(income_max_row,COLUMN()))) -> 0 | BI22: =SUM(INDIRECT(ADDRESS(income_min_row,COLUMN())& ":"& ADDRESS(income_max_row,COLUMN()))) -> 0 | BJ22: =SUM(INDIRECT(ADDRESS(income_min_row,COLUMN())& ":"& ADDRESS(income_max_row,COLUMN()))) -> 0 | BK22: =SUM(INDIRECT(ADDRESS(income_min_row,COLUMN())& ":"& ADDRESS(income_max_row,COLUMN()))) -> 0 | BL22: =SUM(INDIRECT(ADDRESS(income_min_row,COLUMN())& ":"& ADDRESS(income_max_row,COLUMN()))) -> 0 | BM22: =SUM(INDIRECT(ADDRESS(income_min_row,COLUMN())& ":"& ADDRESS(income_max_row,COLUMN()))) -> 0 | BN22: =SUM(INDIRECT(ADDRESS(income_min_row,COLUMN())& ":"& ADDRESS(income_max_row,COLUMN()))) -> 0 | BO22: =SUM(INDIRECT(ADDRESS(income_min_row,COLUMN())& ":"& ADDRESS(income_max_row,COLUMN()))) -> 0 | BP22: =SUM(INDIRECT(ADDRESS(income_min_row,COLUMN())& ":"& ADDRESS(income_max_row,COLUMN()))) -> 0 | ... BU22: =SUM(INDIRECT(ADDRESS(income_min_row,COLUMN())& ":"& ADDRESS(income_max_row,COLUMN()))) -> 0 | BW22: =SUM(INDIRECT(ADDRESS(income_min_row,COLUMN())& ":"& ADDRESS(income_max_row,COLUMN()))) -> 0 | BX22: =SUM(INDIRECT(ADDRESS(income_min_row,COLUMN())& ":"& ADDRESS(income_max_row,COLUMN()))) -> 0 | BY22: =SUM(INDIRECT(ADDRESS(income_min_row,COLUMN())& ":"& ADDRESS(income_max_row,COLUMN()))) -> 0 | BZ22: =SUM(INDIRECT(ADDRESS(income_min_row,COLUMN())& ":"& ADDRESS(income_max_row,COLUMN()))) -> 0 | CA22: =SUM(INDIRECT(ADDRESS(income_min_row,COLUMN())& ":"& ADDRESS(income_max_row,COLUMN()))) -> 0 | CB22: =SUM(INDIRECT(ADDRESS(income_min_row,COLUMN())& ":"& ADDRESS(income_max_row,COLUMN()))) -> 0 | CC22: =SUM(INDIRECT(ADDRESS(income_min_row,COLUMN())& ":"& ADDRESS(income_max_row,COLUMN()))) -> 0 | CD22: =SUM(INDIRECT(ADDRESS(income_min_row,COLUMN())& ":"& ADDRESS(income_max_row,COLUMN()))) -> 0 | ... CI22: =SUM(INDIRECT(ADDRESS(income_min_row,COLUMN())& ":"& ADDRESS(income_max_row,COLUMN()))) -> 0 | CK22: =SUM(INDIRECT(ADDRESS(income_min_row,COLUMN())& ":"& ADDRESS(income_max_row,COLUMN()))) -> 0 | CL22: =SUM(INDIRECT(ADDRESS(income_min_row,COLUMN())& ":"& ADDRESS(income_max_row,COLUMN()))) -> 0 | CM22: =SUM(INDIRECT(ADDRESS(income_min_row,COLUMN())& ":"& ADDRESS(income_max_row,COLUMN()))) -> 0 | CN22: =SUM(INDIRECT(ADDRESS(income_min_row,COLUMN())& ":"& ADDRESS(income_max_row,COLUMN()))) -> 0 | CO22: =SUM(INDIRECT(ADDRESS(income_min_row,COLUMN())& ":"& ADDRESS(income_max_row,COLUMN()))) -> 0 | CP22: =SUM(INDIRECT(ADDRESS(income_min_row,COLUMN())& ":"& ADDRESS(income_max_row,COLUMN()))) -> 0 | CQ22: =SUM(INDIRECT(ADDRESS(income_min_row,COLUMN())& ":"& ADDRESS(income_max_row,COLUMN()))) -> 0 | CR22: =SUM(INDIRECT(ADDRESS(income_min_row,COLUMN())& ":"& ADDRESS(income_max_row,COLUMN()))) -> 0 | ... CW22: =SUM(INDIRECT(ADDRESS(income_min_row,COLUMN())& ":"& ADDRESS(income_max_row,COLUMN()))) -> 0 | CY22: =SUM(INDIRECT(ADDRESS(income_min_row,COLUMN())& ":"& ADDRESS(income_max_row,COLUMN()))) -> 0 | CZ22: =SUM(INDIRECT(ADDRESS(income_min_row,COLUMN())& ":"& ADDRESS(income_max_row,COLUMN()))) -> 0 | DA22: =SUM(INDIRECT(ADDRESS(income_min_row,COLUMN())& ":"& ADDRESS(income_max_row,COLUMN()))) -> 0 | DB22: =SUM(INDIRECT(ADDRESS(income_min_row,COLUMN())& ":"& ADDRESS(income_max_row,COLUMN()))) -> 0 | DC22: =SUM(INDIRECT(ADDRESS(income_min_row,COLUMN())& ":"& ADDRESS(income_max_row,COLUMN()))) -> 0 | DD22: =SUM(INDIRECT(ADDRESS(income_min_row,COLUMN())& ":"& ADDRESS(income_max_row,COLUMN()))) -> 0 | DE22: =SUM(INDIRECT(ADDRESS(income_min_row,COLUMN())& ":"& ADDRESS(income_max_row,COLUMN()))) -> 0 | DF22: =SUM(INDIRECT(ADDRESS(income_min_row,COLUMN())& ":"& ADDRESS(income_max_row,COLUMN()))) -> 0 | ... DK22: =SUM(INDIRECT(ADDRESS(income_min_row,COLUMN())& ":"& ADDRESS(income_max_row,COLUMN()))) -> 0 | DM22: =SUM(INDIRECT(ADDRESS(income_min_row,COLUMN())& ":"& ADDRESS(income_max_row,COLUMN()))) -> 0 | DN22: =SUM(INDIRECT(ADDRESS(income_min_row,COLUMN())& ":"& ADDRESS(income_max_row,COLUMN()))) -> 0 | DO22: =SUM(INDIRECT(ADDRESS(income_min_row,COLUMN())& ":"& ADDRESS(income_max_row,COLUMN()))) -> 0 | DP22: =SUM(INDIRECT(ADDRESS(income_min_row,COLUMN())& ":"& ADDRESS(income_max_row,COLUMN()))) -> 0 | DQ22: =SUM(INDIRECT(ADDRESS(income_min_row,COLUMN())& ":"& ADDRESS(income_max_row,COLUMN()))) -> 0 | DR22: =SUM(INDIRECT(ADDRESS(income_min_row,COLUMN())& ":"& ADDRESS(income_max_row,COLUMN()))) -> 0 | DS22: =SUM(INDIRECT(ADDRESS(income_min_row,COLUMN())& ":"& ADDRESS(income_max_row,COLUMN()))) -> 0 | DT22: =SUM(INDIRECT(ADDRESS(income_min_row,COLUMN())& ":"& ADDRESS(income_max_row,COLUMN()))) -> 0 | ... DY22: =SUM(INDIRECT(ADDRESS(income_min_row,COLUMN())& ":"& ADDRESS(income_max_row,COLUMN()))) -> 0 | EA22: =SUM(INDIRECT(ADDRESS(income_min_row,COLUMN())& ":"& ADDRESS(income_max_row,COLUMN()))) -> 0 | EB22: =SUM(INDIRECT(ADDRESS(income_min_row,COLUMN())& ":"& ADDRESS(income_max_row,COLUMN()))) -> 0 | EC22: =SUM(INDIRECT(ADDRESS(income_min_row,COLUMN())& ":"& ADDRESS(income_max_row,COLUMN()))) -> 0 | ED22: =SUM(INDIRECT(ADDRESS(income_min_row,COLUMN())& ":"& ADDRESS(income_max_row,COLUMN()))) -> 0 | EE22: =SUM(INDIRECT(ADDRESS(income_min_row,COLUMN())& ":"& ADDRESS(income_max_row,COLUMN()))) -> 0 | EF22: =SUM(INDIRECT(ADDRESS(income_min_row,COLUMN())& ":"& ADDRESS(income_max_row,COLUMN()))) -> 0 | EG22: =SUM(INDIRECT(ADDRESS(income_min_row,COLUMN())& ":"& ADDRESS(income_max_row,COLUMN()))) -> 0 | EH22: =SUM(INDIRECT(ADDRESS(income_min_row,COLUMN())& ":"& ADDRESS(income_max_row,COLUMN()))) -> 0 | ... EM22: =SUM(INDIRECT(ADDRESS(income_min_row,COLUMN())& ":"& ADDRESS(income_max_row,COLUMN()))) -> 0 | EO22: =SUM(INDIRECT(ADDRESS(income_min_row,COLUMN())& ":"& ADDRESS(income_max_row,COLUMN()))) -> 0 | EP22: =SUM(INDIRECT(ADDRESS(income_min_row,COLUMN())& ":"& ADDRESS(income_max_row,COLUMN()))) -> 0 | EQ22: =SUM(INDIRECT(ADDRESS(income_min_row,COLUMN())& ":"& ADDRESS(income_max_row,COLUMN()))) -> 0 | ER22: =SUM(INDIRECT(ADDRESS(income_min_row,COLUMN())& ":"& ADDRESS(income_max_row,COLUMN()))) -> 0 | ES22: =SUM(INDIRECT(ADDRESS(income_min_row,COLUMN())& ":"& ADDRESS(income_max_row,COLUMN()))) -> 0 | ET22: =SUM(INDIRECT(ADDRESS(income_min_row,COLUMN())& ":"& ADDRESS(income_max_row,COLUMN()))) -> 0 | EU22: =SUM(INDIRECT(ADDRESS(income_min_row,COLUMN())& ":"& ADDRESS(income_max_row,COLUMN()))) -> 0 | EV22: =SUM(INDIRECT(ADDRESS(income_min_row,COLUMN())& ":"& ADDRESS(income_max_row,COLUMN()))) -> 0 | ... FA22: =SUM(INDIRECT(ADDRESS(income_min_row,COLUMN())& ":"& ADDRESS(income_max_row,COLUMN()))) -> 0
C25: Expenses | E25: =DATE(E$5,1,1) -> 44562 | F25: =DATE(E$5,2,1) -> 44593 | G25: =DATE(E$5,3,1) -> 44621 | H25: =DATE(E$5,4,1) -> 44652 | I25: =DATE(E$5,5,1) -> 44682 | J25: =DATE(E$5,6,1) -> 44713 | K25: =DATE(E$5,7,1) -> 44743 | L25: =DATE(E$5,8,1) -> 44774 | M25: =DATE(E$5,9,1) -> 44805 | N25: =DATE(E$5,10,1) -> 44835 | O25: =DATE(E$5,11,1) -> 44866 | P25: =DATE(E$5,12,1) -> 44896 | Q25: =E$5 -> 2022 | S25: =DATE(S$5,1,1) -> 44927 | T25: =DATE(S$5,2,1) -> 44958 | U25: =DATE(S$5,3,1) -> 44986 | V25: =DATE(S$5,4,1) -> 45017 | W25: =DATE(S$5,5,1) -> 45047 | X25: =DATE(S$5,6,1) -> 45078 | Y25: =DATE(S$5,7,1) -> 45108 | Z25: =DATE(S$5,8,1) -> 45139 | AA25: =DATE(S$5,9,1) -> 45170 | AB25: =DATE(S$5,10,1) -> 45200 | AC25: =DATE(S$5,11,1) -> 45231 | AD25: =DATE(S$5,12,1) -> 45261 | AE25: =S$5 -> 2023 | AG25: =DATE(AG$5,1,1) -> 45292 | AH25: =DATE(AG$5,2,1) -> 45323 | AI25: =DATE(AG$5,3,1) -> 45352 | AJ25: =DATE(AG$5,4,1) -> 45383 | AK25: =DATE(AG$5,5,1) -> 45413 | AL25: =DATE(AG$5,6,1) -> 45444 | AM25: =DATE(AG$5,7,1) -> 45474 | AN25: =DATE(AG$5,8,1) -> 45505 | AO25: =DATE(AG$5,9,1) -> 45536 | AP25: =DATE(AG$5,10,1) -> 45566 | AQ25: =DATE(AG$5,11,1) -> 45597 | AR25: =DATE(AG$5,12,1) -> 45627 | AS25: =AG$5 -> 2024 | AU25: =DATE(AU$5,1,1) -> 45658 | AV25: =DATE(AU$5,2,1) -> 45689 | AW25: =DATE(AU$5,3,1) -> 45717 | AX25: =DATE(AU$5,4,1) -> 45748 | AY25: =DATE(AU$5,5,1) -> 45778 | AZ25: =DATE(AU$5,6,1) -> 45809 | BA25: =DATE(AU$5,7,1) -> 45839 | BB25: =DATE(AU$5,8,1) -> 45870 | BC25: =DATE(AU$5,9,1) -> 45901 | BD25: =DATE(AU$5,10,1) -> 45931 | BE25: =DATE(AU$5,11,1) -> 45962 | BF25: =DATE(AU$5,12,1) -> 45992 | BG25: =AU$5 -> 2025 | BI25: =DATE(BI$5,1,1) -> 46023 | BJ25: =DATE(BI$5,2,1) -> 46054 | BK25: =DATE(BI$5,3,1) -> 46082 | BL25: =DATE(BI$5,4,1) -> 46113 | BM25: =DATE(BI$5,5,1) -> 46143 | BN25: =DATE(BI$5,6,1) -> 46174 | BO25: =DATE(BI$5,7,1) -> 46204 | BP25: =DATE(BI$5,8,1) -> 46235 | BQ25: =DATE(BI$5,9,1) -> 46266 | BR25: =DATE(BI$5,10,1) -> 46296 | BS25: =DATE(BI$5,11,1) -> 46327 | BT25: =DATE(BI$5,12,1) -> 46357 | BU25: =BI$5 -> 2026 | BW25: =DATE(BW$5,1,1) -> 46388 | BX25: =DATE(BW$5,2,1) -> 46419 | BY25: =DATE(BW$5,3,1) -> 46447 | BZ25: =DATE(BW$5,4,1) -> 46478 | CA25: =DATE(BW$5,5,1) -> 46508 | CB25: =DATE(BW$5,6,1) -> 46539 | CC25: =DATE(BW$5,7,1) -> 46569 | CD25: =DATE(BW$5,8,1) -> 46600 | CE25: =DATE(BW$5,9,1) -> 46631 | CF25: =DATE(BW$5,10,1) -> 46661 | CG25: =DATE(BW$5,11,1) -> 46692 | CH25: =DATE(BW$5,12,1) -> 46722 | CI25: =BW$5 -> 2027 | CK25: =DATE(CK$5,1,1) -> 46753 | CL25: =DATE(CK$5,2,1) -> 46784 | CM25: =DATE(CK$5,3,1) -> 46813 | CN25: =DATE(CK$5,4,1) -> 46844 | CO25: =DATE(CK$5,5,1) -> 46874 | CP25: =DATE(CK$5,6,1) -> 46905 | CQ25: =DATE(CK$5,7,1) -> 46935 | CR25: =DATE(CK$5,8,1) -> 46966 | CS25: =DATE(CK$5,9,1) -> 46997 | CT25: =DATE(CK$5,10,1) -> 47027 | CU25: =DATE(CK$5,11,1) -> 47058 | CV25: =DATE(CK$5,12,1) -> 47088 | CW25: =CK$5 -> 2028 | CY25: =DATE(CY$5,1,1) -> 47119 | CZ25: =DATE(CY$5,2,1) -> 47150 | DA25: =DATE(CY$5,3,1) -> 47178 | DB25: =DATE(CY$5,4,1) -> 47209 | DC25: =DATE(CY$5,5,1) -> 47239 | DD25: =DATE(CY$5,6,1) -> 47270 | DE25: =DATE(CY$5,7,1) -> 47300 | DF25: =DATE(CY$5,8,1) -> 47331 | DG25: =DATE(CY$5,9,1) -> 47362 | DH25: =DATE(CY$5,10,1) -> 47392 | DI25: =DATE(CY$5,11,1) -> 47423 | DJ25: =DATE(CY$5,12,1) -> 47453 | DK25: =CY$5 -> 2029 | DM25: =DATE(DM$5,1,1) -> 47484 | DN25: =DATE(DM$5,2,1) -> 47515 | DO25: =DATE(DM$5,3,1) -> 47543 | DP25: =DATE(DM$5,4,1) -> 47574 | DQ25: =DATE(DM$5,5,1) -> 47604 | DR25: =DATE(DM$5,6,1) -> 47635 | DS25: =DATE(DM$5,7,1) -> 47665 | DT25: =DATE(DM$5,8,1) -> 47696 | DU25: =DATE(DM$5,9,1) -> 47727 | DV25: =DATE(DM$5,10,1) -> 47757 | DW25: =DATE(DM$5,11,1) -> 47788 | DX25: =DATE(DM$5,12,1) -> 47818 | DY25: =DM$5 -> 2030 | EA25: =DATE(EA$5,1,1) -> 47849 | EB25: =DATE(EA$5,2,1) -> 47880 | EC25: =DATE(EA$5,3,1) -> 47908 | ED25: =DATE(EA$5,4,1) -> 47939 | EE25: =DATE(EA$5,5,1) -> 47969 | EF25: =DATE(EA$5,6,1) -> 48000 | EG25: =DATE(EA$5,7,1) -> 48030 | EH25: =DATE(EA$5,8,1) -> 48061 | EI25: =DATE(EA$5,9,1) -> 48092 | EJ25: =DATE(EA$5,10,1) -> 48122 | EK25: =DATE(EA$5,11,1) -> 48153 | EL25: =DATE(EA$5,12,1) -> 48183 | EM25: =EA$5 -> 2031 | EO25: =DATE(EO$5,1,1) -> 48214 | EP25: =DATE(EO$5,2,1) -> 48245 | EQ25: =DATE(EO$5,3,1) -> 48274 | ER25: =DATE(EO$5,4,1) -> 48305 | ES25: =DATE(EO$5,5,1) -> 48335 | ET25: =DATE(EO$5,6,1) -> 48366 | EU25: =DATE(EO$5,7,1) -> 48396 | EV25: =DATE(EO$5,8,1) -> 48427 | EW25: =DATE(EO$5,9,1) -> 48458 | EX25: =DATE(EO$5,10,1) -> 48488 | EY25: =DATE(EO$5,11,1) -> 48519 | EZ25: =DATE(EO$5,12,1) -> 48549 | FA25: =EO$5 -> 2032
C26: Housing | E26: 1200 | F26: 1200 | G26: 1200 | H26: 1200 | I26: 1200 | J26: 1200 | K26: 1200 | L26: 1200 | M26: 1200 | N26: 1200 | O26: 1200 | P26: 1200 | Q26: =SUM(E26:P26) -> 14400 | AE26: =SUM(S26:AD26) -> 0 | AS26: =SUM(AG26:AR26) -> 0 | BG26: =SUM(AU26:BF26) -> 0 | BU26: =SUM(BI26:BT26) -> 0 | CI26: =SUM(BW26:CH26) -> 0 | CW26: =SUM(CK26:CV26) -> 0 | DK26: =SUM(CY26:DJ26) -> 0 | DY26: =SUM(DM26:DX26) -> 0 | EM26: =SUM(EA26:EL26) -> 0 | FA26: =SUM(EO26:EZ26) -> 0
C27: Utilities | E27: 300 | F27: 300 | G27: 300 | H27: 300 | I27: 300 | J27: 300 | K27: 300 | L27: 300 | M27: 300 | N27: 300 | O27: 300 | P27: 300 | Q27: =SUM(E27:P27) -> 3600 | AE27: =SUM(S27:AD27) -> 0 | AS27: =SUM(AG27:AR27) -> 0 | BG27: =SUM(AU27:BF27) -> 0 | BU27: =SUM(BI27:BT27) -> 0 | CI27: =SUM(BW27:CH27) -> 0 | CW27: =SUM(CK27:CV27) -> 0 | DK27: =SUM(CY27:DJ27) -> 0 | DY27: =SUM(DM27:DX27) -> 0 | EM27: =SUM(EA27:EL27) -> 0 | FA27: =SUM(EO27:EZ27) -> 0
C28: Groceries | E28: 350 | F28: 350 | G28: 350 | H28: 350 | I28: 350 | J28: 350 | K28: 350 | L28: 350 | M28: 350 | N28: 350 | O28: 350 | P28: 350 | Q28: =SUM(E28:P28) -> 4200 | AE28: =SUM(S28:AD28) -> 0 | AS28: =SUM(AG28:AR28) -> 0 | BG28: =SUM(AU28:BF28) -> 0 | BU28: =SUM(BI28:BT28) -> 0 | CI28: =SUM(BW28:CH28) -> 0 | CW28: =SUM(CK28:CV28) -> 0 | DK28: =SUM(CY28:DJ28) -> 0 | DY28: =SUM(DM28:DX28) -> 0 | EM28: =SUM(EA28:EL28) -> 0 | FA28: =SUM(EO28:EZ28) -> 0
C29: Transportation | E29: 300 | F29: 300 | G29: 300 | H29: 300 | I29: 300 | J29: 300 | K29: 300 | L29: 300 | M29: 300 | N29: 300 | O29: 300 | P29: 300 | Q29: =SUM(E29:P29) -> 3600 | AE29: =SUM(S29:AD29) -> 0 | AS29: =SUM(AG29:AR29) -> 0 | BG29: =SUM(AU29:BF29) -> 0 | BU29: =SUM(BI29:BT29) -> 0 | CI29: =SUM(BW29:CH29) -> 0 | CW29: =SUM(CK29:CV29) -> 0 | DK29: =SUM(CY29:DJ29) -> 0 | DY29: =SUM(DM29:DX29) -> 0 | EM29: =SUM(EA29:EL29) -> 0 | FA29: =SUM(EO29:EZ29) -> 0
C30: Insurances | E30: 0 | F30: - | G30: 150 | H30: - | I30: - | J30: 150 | K30: - | L30: - | M30: 150 | N30: - | O30: - | P30: 150 | Q30: =SUM(E30:P30) -> 600 | AE30: =SUM(S30:AD30) -> 0 | AS30: =SUM(AG30:AR30) -> 0 | BG30: =SUM(AU30:BF30) -> 0 | BU30: =SUM(BI30:BT30) -> 0 | CI30: =SUM(BW30:CH30) -> 0 | CW30: =SUM(CK30:CV30) -> 0 | DK30: =SUM(CY30:DJ30) -> 0 | DY30: =SUM(DM30:DX30) -> 0 | EM30: =SUM(EA30:EL30) -> 0 | FA30: =SUM(EO30:EZ30) -> 0
C31: Clothing | E31: 200 | F31: 200 | G31: 200 | H31: 200 | I31: 200 | J31: 200 | K31: 200 | L31: 200 | M31: 200 | N31: 200 | O31: 200 | P31: 200 | Q31: =SUM(E31:P31) -> 2400 | AE31: =SUM(S31:AD31) -> 0 | AS31: =SUM(AG31:AR31) -> 0 | BG31: =SUM(AU31:BF31) -> 0 | BU31: =SUM(BI31:BT31) -> 0 | CI31: =SUM(BW31:CH31) -> 0 | CW31: =SUM(CK31:CV31) -> 0 | DK31: =SUM(CY31:DJ31) -> 0 | DY31: =SUM(DM31:DX31) -> 0 | EM31: =SUM(EA31:EL31) -> 0 | FA31: =SUM(EO31:EZ31) -> 0
C32: Body Care & Medicine | E32: 200 | F32: 200 | G32: 200 | H32: 200 | I32: 200 | J32: 200 | K32: 200 | L32: 200 | M32: 200 | N32: 200 | O32: 200 | P32: 200 | Q32: =SUM(E32:P32) -> 2400 | AE32: =SUM(S32:AD32) -> 0 | AS32: =SUM(AG32:AR32) -> 0 | BG32: =SUM(AU32:BF32) -> 0 | BU32: =SUM(BI32:BT32) -> 0 | CI32: =SUM(BW32:CH32) -> 0 | CW32: =SUM(CK32:CV32) -> 0 | DK32: =SUM(CY32:DJ32) -> 0 | DY32: =SUM(DM32:DX32) -> 0 | EM32: =SUM(EA32:EL32) -> 0 | FA32: =SUM(EO32:EZ32) -> 0
C33: Media | E33: 50 | F33: 50 | G33: 50 | H33: 50 | I33: 50 | J33: 50 | K33: 50 | L33: 50 | M33: 50 | N33: 50 | O33: 50 | P33: 50 | Q33: =SUM(E33:P33) -> 600 | AE33: =SUM(S33:AD33) -> 0 | AS33: =SUM(AG33:AR33) -> 0 | BG33: =SUM(AU33:BF33) -> 0 | BU33: =SUM(BI33:BT33) -> 0 | CI33: =SUM(BW33:CH33) -> 0 | CW33: =SUM(CK33:CV33) -> 0 | DK33: =SUM(CY33:DJ33) -> 0 | DY33: =SUM(DM33:DX33) -> 0 | EM33: =SUM(EA33:EL33) -> 0 | FA33: =SUM(EO33:EZ33) -> 0
C34: Fun & Vacation | E34: 300 | F34: 300 | G34: 300 | H34: 1200 | I34: 300 | J34: 300 | K34: 300 | L34: 1500 | M34: 300 | N34: 300 | O34: 300 | P34: 600 | Q34: =SUM(E34:P34) -> 6000 | AE34: =SUM(S34:AD34) -> 0 | AS34: =SUM(AG34:AR34) -> 0 | BG34: =SUM(AU34:BF34) -> 0 | BU34: =SUM(BI34:BT34) -> 0 | CI34: =SUM(BW34:CH34) -> 0 | CW34: =SUM(CK34:CV34) -> 0 | DK34: =SUM(CY34:DJ34) -> 0 | DY34: =SUM(DM34:DX34) -> 0 | EM34: =SUM(EA34:EL34) -> 0 | FA34: =SUM(EO34:EZ34) -> 0
C35: Enter Expenses category | Q35: =SUM(E35:P35) -> 0 | AE35: =SUM(S35:AD35) -> 0 | AS35: =SUM(AG35:AR35) -> 0 | BG35: =SUM(AU35:BF35) -> 0 | BU35: =SUM(BI35:BT35) -> 0 | CI35: =SUM(BW35:CH35) -> 0 | CW35: =SUM(CK35:CV35) -> 0 | DK35: =SUM(CY35:DJ35) -> 0 | DY35: =SUM(DM35:DX35) -> 0 | EM35: =SUM(EA35:EL35) -> 0 | FA35: =SUM(EO35:EZ35) -> 0
C36: Enter Expenses category | Q36: =SUM(E36:P36) -> 0 | AE36: =SUM(S36:AD36) -> 0 | AS36: =SUM(AG36:AR36) -> 0 | BG36: =SUM(AU36:BF36) -> 0 | BU36: =SUM(BI36:BT36) -> 0 | CI36: =SUM(BW36:CH36) -> 0 | CW36: =SUM(CK36:CV36) -> 0 | DK36: =SUM(CY36:DJ36) -> 0 | DY36: =SUM(DM36:DX36) -> 0 | EM36: =SUM(EA36:EL36) -> 0 | FA36: =SUM(EO36:EZ36) -> 0
C37: Total | E37: =SUM(INDIRECT(ADDRESS(expenses_min_row,COLUMN())& ":"& ADDRESS(expenses_max_row,COLUMN()))) -> 2900 | F37: =SUM(INDIRECT(ADDRESS(expenses_min_row,COLUMN())& ":"& ADDRESS(expenses_max_row,COLUMN()))) -> 2900 | G37: =SUM(INDIRECT(ADDRESS(expenses_min_row,COLUMN())& ":"& ADDRESS(expenses_max_row,COLUMN()))) -> 3050 | H37: =SUM(INDIRECT(ADDRESS(expenses_min_row,COLUMN())& ":"& ADDRESS(expenses_max_row,COLUMN()))) -> 3800 | I37: =SUM(INDIRECT(ADDRESS(expenses_min_row,COLUMN())& ":"& ADDRESS(expenses_max_row,COLUMN()))) -> 2900 | J37: =SUM(INDIRECT(ADDRESS(expenses_min_row,COLUMN())& ":"& ADDRESS(expenses_max_row,COLUMN()))) -> 3050 | K37: =SUM(INDIRECT(ADDRESS(expenses_min_row,COLUMN())& ":"& ADDRESS(expenses_max_row,COLUMN()))) -> 2900 | L37: =SUM(INDIRECT(ADDRESS(expenses_min_row,COLUMN())& ":"& ADDRESS(expenses_max_row,COLUMN()))) -> 4100 | ... P37: =SUM(INDIRECT(ADDRESS(expenses_min_row,COLUMN())& ":"& ADDRESS(expenses_max_row,COLUMN()))) -> 3350 | Q37: =SUM(E37:P37) -> 37800 | S37: =SUM(INDIRECT(ADDRESS(expenses_min_row,COLUMN())& ":"& ADDRESS(expenses_max_row,COLUMN()))) -> 0 | T37: =SUM(INDIRECT(ADDRESS(expenses_min_row,COLUMN())& ":"& ADDRESS(expenses_max_row,COLUMN()))) -> 0 | U37: =SUM(INDIRECT(ADDRESS(expenses_min_row,COLUMN())& ":"& ADDRESS(expenses_max_row,COLUMN()))) -> 0 | V37: =SUM(INDIRECT(ADDRESS(expenses_min_row,COLUMN())& ":"& ADDRESS(expenses_max_row,COLUMN()))) -> 0 | W37: =SUM(INDIRECT(ADDRESS(expenses_min_row,COLUMN())& ":"& ADDRESS(expenses_max_row,COLUMN()))) -> 0 | X37: =SUM(INDIRECT(ADDRESS(expenses_min_row,COLUMN())& ":"& ADDRESS(expenses_max_row,COLUMN()))) -> 0 | Y37: =SUM(INDIRECT(ADDRESS(expenses_min_row,COLUMN())& ":"& ADDRESS(expenses_max_row,COLUMN()))) -> 0 | Z37: =SUM(INDIRECT(ADDRESS(expenses_min_row,COLUMN())& ":"& ADDRESS(expenses_max_row,COLUMN()))) -> 0 | ... AE37: =SUM(INDIRECT(ADDRESS(expenses_min_row,COLUMN())& ":"& ADDRESS(expenses_max_row,COLUMN()))) -> 0 | AG37: =SUM(INDIRECT(ADDRESS(expenses_min_row,COLUMN())& ":"& ADDRESS(expenses_max_row,COLUMN()))) -> 0 | AH37: =SUM(INDIRECT(ADDRESS(expenses_min_row,COLUMN())& ":"& ADDRESS(expenses_max_row,COLUMN()))) -> 0 | AI37: =SUM(INDIRECT(ADDRESS(expenses_min_row,COLUMN())& ":"& ADDRESS(expenses_max_row,COLUMN()))) -> 0 | AJ37: =SUM(INDIRECT(ADDRESS(expenses_min_row,COLUMN())& ":"& ADDRESS(expenses_max_row,COLUMN()))) -> 0 | AK37: =SUM(INDIRECT(ADDRESS(expenses_min_row,COLUMN())& ":"& ADDRESS(expenses_max_row,COLUMN()))) -> 0 | AL37: =SUM(INDIRECT(ADDRESS(expenses_min_row,COLUMN())& ":"& ADDRESS(expenses_max_row,COLUMN()))) -> 0 | AM37: =SUM(INDIRECT(ADDRESS(expenses_min_row,COLUMN())& ":"& ADDRESS(expenses_max_row,COLUMN()))) -> 0 | AN37: =SUM(INDIRECT(ADDRESS(expenses_min_row,COLUMN())& ":"& ADDRESS(expenses_max_row,COLUMN()))) -> 0 | ... AS37: =SUM(INDIRECT(ADDRESS(expenses_min_row,COLUMN())& ":"& ADDRESS(expenses_max_row,COLUMN()))) -> 0 | AU37: =SUM(INDIRECT(ADDRESS(expenses_min_row,COLUMN())& ":"& ADDRESS(expenses_max_row,COLUMN()))) -> 0 | AV37: =SUM(INDIRECT(ADDRESS(expenses_min_row,COLUMN())& ":"& ADDRESS(expenses_max_row,COLUMN()))) -> 0 | AW37: =SUM(INDIRECT(ADDRESS(expenses_min_row,COLUMN())& ":"& ADDRESS(expenses_max_row,COLUMN()))) -> 0 | AX37: =SUM(INDIRECT(ADDRESS(expenses_min_row,COLUMN())& ":"& ADDRESS(expenses_max_row,COLUMN()))) -> 0 | AY37: =SUM(INDIRECT(ADDRESS(expenses_min_row,COLUMN())& ":"& ADDRESS(expenses_max_row,COLUMN()))) -> 0 | AZ37: =SUM(INDIRECT(ADDRESS(expenses_min_row,COLUMN())& ":"& ADDRESS(expenses_max_row,COLUMN()))) -> 0 | BA37: =SUM(INDIRECT(ADDRESS(expenses_min_row,COLUMN())& ":"& ADDRESS(expenses_max_row,COLUMN()))) -> 0 | BB37: =SUM(INDIRECT(ADDRESS(expenses_min_row,COLUMN())& ":"& ADDRESS(expenses_max_row,COLUMN()))) -> 0 | ... BG37: =SUM(INDIRECT(ADDRESS(expenses_min_row,COLUMN())& ":"& ADDRESS(expenses_max_row,COLUMN()))) -> 0 | BI37: =SUM(INDIRECT(ADDRESS(expenses_min_row,COLUMN())& ":"& ADDRESS(expenses_max_row,COLUMN()))) -> 0 | BJ37: =SUM(INDIRECT(ADDRESS(expenses_min_row,COLUMN())& ":"& ADDRESS(expenses_max_row,COLUMN()))) -> 0 | BK37: =SUM(INDIRECT(ADDRESS(expenses_min_row,COLUMN())& ":"& ADDRESS(expenses_max_row,COLUMN()))) -> 0 | BL37: =SUM(INDIRECT(ADDRESS(expenses_min_row,COLUMN())& ":"& ADDRESS(expenses_max_row,COLUMN()))) -> 0 | BM37: =SUM(INDIRECT(ADDRESS(expenses_min_row,COLUMN())& ":"& ADDRESS(expenses_max_row,COLUMN()))) -> 0 | BN37: =SUM(INDIRECT(ADDRESS(expenses_min_row,COLUMN())& ":"& ADDRESS(expenses_max_row,COLUMN()))) -> 0 | BO37: =SUM(INDIRECT(ADDRESS(expenses_min_row,COLUMN())& ":"& ADDRESS(expenses_max_row,COLUMN()))) -> 0 | BP37: =SUM(INDIRECT(ADDRESS(expenses_min_row,COLUMN())& ":"& ADDRESS(expenses_max_row,COLUMN()))) -> 0 | ... BU37: =SUM(INDIRECT(ADDRESS(expenses_min_row,COLUMN())& ":"& ADDRESS(expenses_max_row,COLUMN()))) -> 0 | BW37: =SUM(INDIRECT(ADDRESS(expenses_min_row,COLUMN())& ":"& ADDRESS(expenses_max_row,COLUMN()))) -> 0 | BX37: =SUM(INDIRECT(ADDRESS(expenses_min_row,COLUMN())& ":"& ADDRESS(expenses_max_row,COLUMN()))) -> 0 | BY37: =SUM(INDIRECT(ADDRESS(expenses_min_row,COLUMN())& ":"& ADDRESS(expenses_max_row,COLUMN()))) -> 0 | BZ37: =SUM(INDIRECT(ADDRESS(expenses_min_row,COLUMN())& ":"& ADDRESS(expenses_max_row,COLUMN()))) -> 0 | CA37: =SUM(INDIRECT(ADDRESS(expenses_min_row,COLUMN())& ":"& ADDRESS(expenses_max_row,COLUMN()))) -> 0 | CB37: =SUM(INDIRECT(ADDRESS(expenses_min_row,COLUMN())& ":"& ADDRESS(expenses_max_row,COLUMN()))) -> 0 | CC37: =SUM(INDIRECT(ADDRESS(expenses_min_row,COLUMN())& ":"& ADDRESS(expenses_max_row,COLUMN()))) -> 0 | CD37: =SUM(INDIRECT(ADDRESS(expenses_min_row,COLUMN())& ":"& ADDRESS(expenses_max_row,COLUMN()))) -> 0 | ... CI37: =SUM(INDIRECT(ADDRESS(expenses_min_row,COLUMN())& ":"& ADDRESS(expenses_max_row,COLUMN()))) -> 0 | CK37: =SUM(INDIRECT(ADDRESS(expenses_min_row,COLUMN())& ":"& ADDRESS(expenses_max_row,COLUMN()))) -> 0 | CL37: =SUM(INDIRECT(ADDRESS(expenses_min_row,COLUMN())& ":"& ADDRESS(expenses_max_row,COLUMN()))) -> 0 | CM37: =SUM(INDIRECT(ADDRESS(expenses_min_row,COLUMN())& ":"& ADDRESS(expenses_max_row,COLUMN()))) -> 0 | CN37: =SUM(INDIRECT(ADDRESS(expenses_min_row,COLUMN())& ":"& ADDRESS(expenses_max_row,COLUMN()))) -> 0 | CO37: =SUM(INDIRECT(ADDRESS(expenses_min_row,COLUMN())& ":"& ADDRESS(expenses_max_row,COLUMN()))) -> 0 | CP37: =SUM(INDIRECT(ADDRESS(expenses_min_row,COLUMN())& ":"& ADDRESS(expenses_max_row,COLUMN()))) -> 0 | CQ37: =SUM(INDIRECT(ADDRESS(expenses_min_row,COLUMN())& ":"& ADDRESS(expenses_max_row,COLUMN()))) -> 0 | CR37: =SUM(INDIRECT(ADDRESS(expenses_min_row,COLUMN())& ":"& ADDRESS(expenses_max_row,COLUMN()))) -> 0 | ... CW37: =SUM(INDIRECT(ADDRESS(expenses_min_row,COLUMN())& ":"& ADDRESS(expenses_max_row,COLUMN()))) -> 0 | CY37: =SUM(INDIRECT(ADDRESS(expenses_min_row,COLUMN())& ":"& ADDRESS(expenses_max_row,COLUMN()))) -> 0 | CZ37: =SUM(INDIRECT(ADDRESS(expenses_min_row,COLUMN())& ":"& ADDRESS(expenses_max_row,COLUMN()))) -> 0 | DA37: =SUM(INDIRECT(ADDRESS(expenses_min_row,COLUMN())& ":"& ADDRESS(expenses_max_row,COLUMN()))) -> 0 | DB37: =SUM(INDIRECT(ADDRESS(expenses_min_row,COLUMN())& ":"& ADDRESS(expenses_max_row,COLUMN()))) -> 0 | DC37: =SUM(INDIRECT(ADDRESS(expenses_min_row,COLUMN())& ":"& ADDRESS(expenses_max_row,COLUMN()))) -> 0 | DD37: =SUM(INDIRECT(ADDRESS(expenses_min_row,COLUMN())& ":"& ADDRESS(expenses_max_row,COLUMN()))) -> 0 | DE37: =SUM(INDIRECT(ADDRESS(expenses_min_row,COLUMN())& ":"& ADDRESS(expenses_max_row,COLUMN()))) -> 0 | DF37: =SUM(INDIRECT(ADDRESS(expenses_min_row,COLUMN())& ":"& ADDRESS(expenses_max_row,COLUMN()))) -> 0 | ... DK37: =SUM(INDIRECT(ADDRESS(expenses_min_row,COLUMN())& ":"& ADDRESS(expenses_max_row,COLUMN()))) -> 0 | DM37: =SUM(INDIRECT(ADDRESS(expenses_min_row,COLUMN())& ":"& ADDRESS(expenses_max_row,COLUMN()))) -> 0 | DN37: =SUM(INDIRECT(ADDRESS(expenses_min_row,COLUMN())& ":"& ADDRESS(expenses_max_row,COLUMN()))) -> 0 | DO37: =SUM(INDIRECT(ADDRESS(expenses_min_row,COLUMN())& ":"& ADDRESS(expenses_max_row,COLUMN()))) -> 0 | DP37: =SUM(INDIRECT(ADDRESS(expenses_min_row,COLUMN())& ":"& ADDRESS(expenses_max_row,COLUMN()))) -> 0 | DQ37: =SUM(INDIRECT(ADDRESS(expenses_min_row,COLUMN())& ":"& ADDRESS(expenses_max_row,COLUMN()))) -> 0 | DR37: =SUM(INDIRECT(ADDRESS(expenses_min_row,COLUMN())& ":"& ADDRESS(expenses_max_row,COLUMN()))) -> 0 | DS37: =SUM(INDIRECT(ADDRESS(expenses_min_row,COLUMN())& ":"& ADDRESS(expenses_max_row,COLUMN()))) -> 0 | DT37: =SUM(INDIRECT(ADDRESS(expenses_min_row,COLUMN())& ":"& ADDRESS(expenses_max_row,COLUMN()))) -> 0 | ... DY37: =SUM(INDIRECT(ADDRESS(expenses_min_row,COLUMN())& ":"& ADDRESS(expenses_max_row,COLUMN()))) -> 0 | EA37: =SUM(INDIRECT(ADDRESS(expenses_min_row,COLUMN())& ":"& ADDRESS(expenses_max_row,COLUMN()))) -> 0 | EB37: =SUM(INDIRECT(ADDRESS(expenses_min_row,COLUMN())& ":"& ADDRESS(expenses_max_row,COLUMN()))) -> 0 | EC37: =SUM(INDIRECT(ADDRESS(expenses_min_row,COLUMN())& ":"& ADDRESS(expenses_max_row,COLUMN()))) -> 0 | ED37: =SUM(INDIRECT(ADDRESS(expenses_min_row,COLUMN())& ":"& ADDRESS(expenses_max_row,COLUMN()))) -> 0 | EE37: =SUM(INDIRECT(ADDRESS(expenses_min_row,COLUMN())& ":"& ADDRESS(expenses_max_row,COLUMN()))) -> 0 | EF37: =SUM(INDIRECT(ADDRESS(expenses_min_row,COLUMN())& ":"& ADDRESS(expenses_max_row,COLUMN()))) -> 0 | EG37: =SUM(INDIRECT(ADDRESS(expenses_min_row,COLUMN())& ":"& ADDRESS(expenses_max_row,COLUMN()))) -> 0 | EH37: =SUM(INDIRECT(ADDRESS(expenses_min_row,COLUMN())& ":"& ADDRESS(expenses_max_row,COLUMN()))) -> 0 | ... EM37: =SUM(INDIRECT(ADDRESS(expenses_min_row,COLUMN())& ":"& ADDRESS(expenses_max_row,COLUMN()))) -> 0 | EO37: =SUM(INDIRECT(ADDRESS(expenses_min_row,COLUMN())& ":"& ADDRESS(expenses_max_row,COLUMN()))) -> 0 | EP37: =SUM(INDIRECT(ADDRESS(expenses_min_row,COLUMN())& ":"& ADDRESS(expenses_max_row,COLUMN()))) -> 0 | EQ37: =SUM(INDIRECT(ADDRESS(expenses_min_row,COLUMN())& ":"& ADDRESS(expenses_max_row,COLUMN()))) -> 0 | ER37: =SUM(INDIRECT(ADDRESS(expenses_min_row,COLUMN())& ":"& ADDRESS(expenses_max_row,COLUMN()))) -> 0 | ES37: =SUM(INDIRECT(ADDRESS(expenses_min_row,COLUMN())& ":"& ADDRESS(expenses_max_row,COLUMN()))) -> 0 | ET37: =SUM(INDIRECT(ADDRESS(expenses_min_row,COLUMN())& ":"& ADDRESS(expenses_max_row,COLUMN()))) -> 0 | EU37: =SUM(INDIRECT(ADDRESS(expenses_min_row,COLUMN())& ":"& ADDRESS(expenses_max_row,COLUMN()))) -> 0 | EV37: =SUM(INDIRECT(ADDRESS(expenses_min_row,COLUMN())& ":"& ADDRESS(expenses_max_row,COLUMN()))) -> 0 | ... FA37: =SUM(INDIRECT(ADDRESS(expenses_min_row,COLUMN())& ":"& ADDRESS(expenses_max_row,COLUMN()))) -> 0
C40: Savings | E40: =DATE(E$5,1,1) -> 44562 | F40: =DATE(E$5,2,1) -> 44593 | G40: =DATE(E$5,3,1) -> 44621 | H40: =DATE(E$5,4,1) -> 44652 | I40: =DATE(E$5,5,1) -> 44682 | J40: =DATE(E$5,6,1) -> 44713 | K40: =DATE(E$5,7,1) -> 44743 | L40: =DATE(E$5,8,1) -> 44774 | M40: =DATE(E$5,9,1) -> 44805 | N40: =DATE(E$5,10,1) -> 44835 | O40: =DATE(E$5,11,1) -> 44866 | P40: =DATE(E$5,12,1) -> 44896 | Q40: =E$5 -> 2022 | S40: =DATE(S$5,1,1) -> 44927 | T40: =DATE(S$5,2,1) -> 44958 | U40: =DATE(S$5,3,1) -> 44986 | V40: =DATE(S$5,4,1) -> 45017 | W40: =DATE(S$5,5,1) -> 45047 | X40: =DATE(S$5,6,1) -> 45078 | Y40: =DATE(S$5,7,1) -> 45108 | Z40: =DATE(S$5,8,1) -> 45139 | AA40: =DATE(S$5,9,1) -> 45170 | AB40: =DATE(S$5,10,1) -> 45200 | AC40: =DATE(S$5,11,1) -> 45231 | AD40: =DATE(S$5,12,1) -> 45261 | AE40: =S$5 -> 2023 | AG40: =DATE(AG$5,1,1) -> 45292 | AH40: =DATE(AG$5,2,1) -> 45323 | AI40: =DATE(AG$5,3,1) -> 45352 | AJ40: =DATE(AG$5,4,1) -> 45383 | AK40: =DATE(AG$5,5,1) -> 45413 | AL40: =DATE(AG$5,6,1) -> 45444 | AM40: =DATE(AG$5,7,1) -> 45474 | AN40: =DATE(AG$5,8,1) -> 45505 | AO40: =DATE(AG$5,9,1) -> 45536 | AP40: =DATE(AG$5,10,1) -> 45566 | AQ40: =DATE(AG$5,11,1) -> 45597 | AR40: =DATE(AG$5,12,1) -> 45627 | AS40: =AG$5 -> 2024 | AU40: =DATE(AU$5,1,1) -> 45658 | AV40: =DATE(AU$5,2,1) -> 45689 | AW40: =DATE(AU$5,3,1) -> 45717 | AX40: =DATE(AU$5,4,1) -> 45748 | AY40: =DATE(AU$5,5,1) -> 45778 | AZ40: =DATE(AU$5,6,1) -> 45809 | BA40: =DATE(AU$5,7,1) -> 45839 | BB40: =DATE(AU$5,8,1) -> 45870 | BC40: =DATE(AU$5,9,1) -> 45901 | BD40: =DATE(AU$5,10,1) -> 45931 | BE40: =DATE(AU$5,11,1) -> 45962 | BF40: =DATE(AU$5,12,1) -> 45992 | BG40: =AU$5 -> 2025 | BI40: =DATE(BI$5,1,1) -> 46023 | BJ40: =DATE(BI$5,2,1) -> 46054 | BK40: =DATE(BI$5,3,1) -> 46082 | BL40: =DATE(BI$5,4,1) -> 46113 | BM40: =DATE(BI$5,5,1) -> 46143 | BN40: =DATE(BI$5,6,1) -> 46174 | BO40: =DATE(BI$5,7,1) -> 46204 | BP40: =DATE(BI$5,8,1) -> 46235 | BQ40: =DATE(BI$5,9,1) -> 46266 | BR40: =DATE(BI$5,10,1) -> 46296 | BS40: =DATE(BI$5,11,1) -> 46327 | BT40: =DATE(BI$5,12,1) -> 46357 | BU40: =BI$5 -> 2026 | BW40: =DATE(BW$5,1,1) -> 46388 | BX40: =DATE(BW$5,2,1) -> 46419 | BY40: =DATE(BW$5,3,1) -> 46447 | BZ40: =DATE(BW$5,4,1) -> 46478 | CA40: =DATE(BW$5,5,1) -> 46508 | CB40: =DATE(BW$5,6,1) -> 46539 | CC40: =DATE(BW$5,7,1) -> 46569 | CD40: =DATE(BW$5,8,1) -> 46600 | CE40: =DATE(BW$5,9,1) -> 46631 | CF40: =DATE(BW$5,10,1) -> 46661 | CG40: =DATE(BW$5,11,1) -> 46692 | CH40: =DATE(BW$5,12,1) -> 46722 | CI40: =BW$5 -> 2027 | CK40: =DATE(CK$5,1,1) -> 46753 | CL40: =DATE(CK$5,2,1) -> 46784 | CM40: =DATE(CK$5,3,1) -> 46813 | CN40: =DATE(CK$5,4,1) -> 46844 | CO40: =DATE(CK$5,5,1) -> 46874 | CP40: =DATE(CK$5,6,1) -> 46905 | CQ40: =DATE(CK$5,7,1) -> 46935 | CR40: =DATE(CK$5,8,1) -> 46966 | CS40: =DATE(CK$5,9,1) -> 46997 | CT40: =DATE(CK$5,10,1) -> 47027 | CU40: =DATE(CK$5,11,1) -> 47058 | CV40: =DATE(CK$5,12,1) -> 47088 | CW40: =CK$5 -> 2028 | CY40: =DATE(CY$5,1,1) -> 47119 | CZ40: =DATE(CY$5,2,1) -> 47150 | DA40: =DATE(CY$5,3,1) -> 47178 | DB40: =DATE(CY$5,4,1) -> 47209 | DC40: =DATE(CY$5,5,1) -> 47239 | DD40: =DATE(CY$5,6,1) -> 47270 | DE40: =DATE(CY$5,7,1) -> 47300 | DF40: =DATE(CY$5,8,1) -> 47331 | DG40: =DATE(CY$5,9,1) -> 47362 | DH40: =DATE(CY$5,10,1) -> 47392 | DI40: =DATE(CY$5,11,1) -> 47423 | DJ40: =DATE(CY$5,12,1) -> 47453 | DK40: =CY$5 -> 2029 | DM40: =DATE(DM$5,1,1) -> 47484 | DN40: =DATE(DM$5,2,1) -> 47515 | DO40: =DATE(DM$5,3,1) -> 47543 | DP40: =DATE(DM$5,4,1) -> 47574 | DQ40: =DATE(DM$5,5,1) -> 47604 | DR40: =DATE(DM$5,6,1) -> 47635 | DS40: =DATE(DM$5,7,1) -> 47665 | DT40: =DATE(DM$5,8,1) -> 47696 | DU40: =DATE(DM$5,9,1) -> 47727 | DV40: =DATE(DM$5,10,1) -> 47757 | DW40: =DATE(DM$5,11,1) -> 47788 | DX40: =DATE(DM$5,12,1) -> 47818 | DY40: =DM$5 -> 2030 | EA40: =DATE(EA$5,1,1) -> 47849 | EB40: =DATE(EA$5,2,1) -> 47880 | EC40: =DATE(EA$5,3,1) -> 47908 | ED40: =DATE(EA$5,4,1) -> 47939 | EE40: =DATE(EA$5,5,1) -> 47969 | EF40: =DATE(EA$5,6,1) -> 48000 | EG40: =DATE(EA$5,7,1) -> 48030 | EH40: =DATE(EA$5,8,1) -> 48061 | EI40: =DATE(EA$5,9,1) -> 48092 | EJ40: =DATE(EA$5,10,1) -> 48122 | EK40: =DATE(EA$5,11,1) -> 48153 | EL40: =DATE(EA$5,12,1) -> 48183 | EM40: =EA$5 -> 2031 | EO40: =DATE(EO$5,1,1) -> 48214 | EP40: =DATE(EO$5,2,1) -> 48245 | EQ40: =DATE(EO$5,3,1) -> 48274 | ER40: =DATE(EO$5,4,1) -> 48305 | ES40: =DATE(EO$5,5,1) -> 48335 | ET40: =DATE(EO$5,6,1) -> 48366 | EU40: =DATE(EO$5,7,1) -> 48396 | EV40: =DATE(EO$5,8,1) -> 48427 | EW40: =DATE(EO$5,9,1) -> 48458 | EX40: =DATE(EO$5,10,1) -> 48488 | EY40: =DATE(EO$5,11,1) -> 48519 | EZ40: =DATE(EO$5,12,1) -> 48549 | FA40: =EO$5 -> 2032
C41: Emergency Fund | E41: 1000 | F41: 1000 | G41: 1000 | H41: - | I41: - | J41: - | K41: - | L41: - | M41: - | N41: - | O41: - | P41: - | Q41: =SUM(E41:P41) -> 3000 | AE41: =SUM(S41:AD41) -> 0 | AS41: =SUM(AG41:AR41) -> 0 | BG41: =SUM(AU41:BF41) -> 0 | BU41: =SUM(BI41:BT41) -> 0 | CI41: =SUM(BW41:CH41) -> 0 | CW41: =SUM(CK41:CV41) -> 0 | DK41: =SUM(CY41:DJ41) -> 0 | DY41: =SUM(DM41:DX41) -> 0 | EM41: =SUM(EA41:EL41) -> 0 | FA41: =SUM(EO41:EZ41) -> 0
C42: Retirement Fund | E42: 400 | F42: 400 | G42: 400 | H42: 400 | I42: 400 | J42: 400 | K42: 400 | L42: 400 | M42: 400 | N42: 400 | O42: 400 | P42: 400 | Q42: =SUM(E42:P42) -> 4800 | AE42: =SUM(S42:AD42) -> 0 | AS42: =SUM(AG42:AR42) -> 0 | BG42: =SUM(AU42:BF42) -> 0 | BU42: =SUM(BI42:BT42) -> 0 | CI42: =SUM(BW42:CH42) -> 0 | CW42: =SUM(CK42:CV42) -> 0 | DK42: =SUM(CY42:DJ42) -> 0 | DY42: =SUM(DM42:DX42) -> 0 | EM42: =SUM(EA42:EL42) -> 0 | FA42: =SUM(EO42:EZ42) -> 0
C43: Stock Portfolio | E43: 150 | F43: 150 | G43: 150 | H43: 750 | I43: 750 | J43: 750 | K43: 750 | L43: 750 | M43: 750 | N43: 750 | O43: 750 | P43: 750 | Q43: =SUM(E43:P43) -> 7200 | AE43: =SUM(S43:AD43) -> 0 | AS43: =SUM(AG43:AR43) -> 0 | BG43: =SUM(AU43:BF43) -> 0 | BU43: =SUM(BI43:BT43) -> 0 | CI43: =SUM(BW43:CH43) -> 0 | CW43: =SUM(CK43:CV43) -> 0 | DK43: =SUM(CY43:DJ43) -> 0 | DY43: =SUM(DM43:DX43) -> 0 | EM43: =SUM(EA43:EL43) -> 0 | FA43: =SUM(EO43:EZ43) -> 0
C44: Sinking Fund Down Payment | E44: 0 | F44: 0 | G44: 0 | H44: 600 | I44: 1400 | J44: 1300 | K44: 1500 | L44: 200 | M44: 1300 | N44: 1500 | O44: 1400 | P44: 1000 | Q44: =SUM(E44:P44) -> 10200 | AE44: =SUM(S44:AD44) -> 0 | AS44: =SUM(AG44:AR44) -> 0 | BG44: =SUM(AU44:BF44) -> 0 | BU44: =SUM(BI44:BT44) -> 0 | CI44: =SUM(BW44:CH44) -> 0 | CW44: =SUM(CK44:CV44) -> 0 | DK44: =SUM(CY44:DJ44) -> 0 | DY44: =SUM(DM44:DX44) -> 0 | EM44: =SUM(EA44:EL44) -> 0 | FA44: =SUM(EO44:EZ44) -> 0
C45: Sinking Fund Rest | E45: 200 | F45: 100 | G45: 0 | H45: 100 | I45: 100 | J45: 100 | K45: 100 | L45: 100 | M45: 100 | N45: 100 | O45: 100 | P45: 100 | Q45: =SUM(E45:P45) -> 1200 | AE45: =SUM(S45:AD45) -> 0 | AS45: =SUM(AG45:AR45) -> 0 | BG45: =SUM(AU45:BF45) -> 0 | BU45: =SUM(BI45:BT45) -> 0 | CI45: =SUM(BW45:CH45) -> 0 | CW45: =SUM(CK45:CV45) -> 0 | DK45: =SUM(CY45:DJ45) -> 0 | DY45: =SUM(DM45:DX45) -> 0 | EM45: =SUM(EA45:EL45) -> 0 | FA45: =SUM(EO45:EZ45) -> 0
C46: Enter Savings Category | Q46: =SUM(E46:P46) -> 0 | AE46: =SUM(S46:AD46) -> 0 | AS46: =SUM(AG46:AR46) -> 0 | BG46: =SUM(AU46:BF46) -> 0 | BU46: =SUM(BI46:BT46) -> 0 | CI46: =SUM(BW46:CH46) -> 0 | CW46: =SUM(CK46:CV46) -> 0 | DK46: =SUM(CY46:DJ46) -> 0 | DY46: =SUM(DM46:DX46) -> 0 | EM46: =SUM(EA46:EL46) -> 0 | FA46: =SUM(EO46:EZ46) -> 0
C47: Enter Savings Category | Q47: =SUM(E47:P47) -> 0 | AE47: =SUM(S47:AD47) -> 0 | AS47: =SUM(AG47:AR47) -> 0 | BG47: =SUM(AU47:BF47) -> 0 | BU47: =SUM(BI47:BT47) -> 0 | CI47: =SUM(BW47:CH47) -> 0 | CW47: =SUM(CK47:CV47) -> 0 | DK47: =SUM(CY47:DJ47) -> 0 | DY47: =SUM(DM47:DX47) -> 0 | EM47: =SUM(EA47:EL47) -> 0 | FA47: =SUM(EO47:EZ47) -> 0
C48: Enter Savings Category | Q48: =SUM(E48:P48) -> 0 | AE48: =SUM(S48:AD48) -> 0 | AS48: =SUM(AG48:AR48) -> 0 | BG48: =SUM(AU48:BF48) -> 0 | BU48: =SUM(BI48:BT48) -> 0 | CI48: =SUM(BW48:CH48) -> 0 | CW48: =SUM(CK48:CV48) -> 0 | DK48: =SUM(CY48:DJ48) -> 0 | DY48: =SUM(DM48:DX48) -> 0 | EM48: =SUM(EA48:EL48) -> 0 | FA48: =SUM(EO48:EZ48) -> 0
...

Sheet Budget Tracking
B2: Budget Tracking
B11: Date | C11: Type | D11: Category | E11: Amount | F11: Details | G11: Balance | H11: Effective Date
